Workbook

Sheet ① 使い方
A1: ラグナオンライン バランス設計シート
B3: ■ 触ってよいのは黄色のセルだけです
B4: 黄色 … あなたが書き換えるところ（③パラメータに集めてあります）
B5: 水色 … 自動計算。書き換えると数式が消えるので触らないでください
B7: ■ シートの並び
B8: ② 使い魔一覧 … 全50体の能力値とスキル。Lv1とLv10を並べています
B9: ③ パラメータ … ここだけ書き換えます。ほかのシートはここを見て計算します
B10: ④ ガチャ試算 … 最大レベルにするまでに必要な単発回数とcoin
B11: ⑤ 成長試算 … ランクごとの平均能力値を Lv1〜Lv10 で並べたもの
B12: ⑥ デッキ試算 … 合計COST20以内の編成と、その平均ステータス
B13: ⑦ AIプロンプト … 生成AIに戦闘シミュレーションを頼むための文章
B15: ■ 今回の前提
B16: ・ガチャは単発だけで計算しています（10連・保証枠は考えていません）
... B36: 能力値やスキルは data/master/ の最新の内容を読み込んでいます。

Sheet ② 使い魔一覧
A1: ② 使い魔一覧 — 能力値とスキル
A2: Lv1・Lv10の能力値は③パラメータの成長設定で変わります。「素の値」とスキルは data/master/ の値です。
A3: ※ Lv1の時点で既に1回ぶん成長しています（能力値＝素の値×(1+成長率×レベル)）。
E4: 素の値(Lv0) | H4: Lv1 | K4: Lv10 | N4: ACTIVEスキル | Q4: PASSIVEスキル
A5: 名前 | B5: ランク | C5: COST | D5: 性別 | E5: HP | F5: ATK | G5: SPD | H5: HP | I5: ATK | J5: SPD | K5: HP | L5: ATK | M5: SPD | N5: 名前 | O5: 内容 | P5: 使用回数 | Q5: 名前 | R5: 内容 | S5: 発動タイミング
A6: フェンリル | B6: S | C6: 5 | D6: 男性 | E6: 34 | F6: 11 | G6: 95 | H6: =ROUND(IF('③ パラメータ'!C34="固定",E6+'③ パラメータ'!B28*(1),E6*(1+'③ パラメータ'!D28*(1))),0) | I6: =ROUND(IF('③ パラメータ'!C34="固定",F6+'③ パラメータ'!C28*(1),F6*(1+'③ パラメータ'!E28*(1))),0) | J6: =MIN(100,G6+(INT((1-1)/'③ パラメータ'!C36)+1)*'③ パラメータ'!C35) | K6: =ROUND(IF('③ パラメータ'!C34="固定",E6+'③ パラメータ'!B28*('③ パラメータ'!C32),E6*(1+'③ パラメータ'!D28*('③ パラメータ'!C32))),0) | L6: =ROUND(IF('③ パラメータ'!C34="固定",F6+'③ パラメータ'!C28*('③ パラメータ'!C32),F6*(1+'③ パラメータ'!E28*('③ パラメータ'!C32))),0) | M6: =MIN(100,G6+(INT(('③ パラメータ'!C32-1)/'③ パラメータ'!C36)+1)*'③ パラメータ'!C35) | N6: 神喰らい | O6: 敵1体をACTIVE使用不能（1ターン）にする。 | P6: 1バトル1回 | Q6: 先駆の魔狼 | R6: 各ラウンドで初めて、まだ行動していない敵を攻撃する時、その攻撃のみATK+50%。 | S6: before_attack
A7: スルト | B7: S | C7: 5 | D7: 男性 | E7: 42 | F7: 10 | G7: 18 | H7: =ROUND(IF('③ パラメータ'!C34="固定",E7+'③ パラメータ'!B28*(1),E7*(1+'③ パラメータ'!D28*(1))),0) | I7: =ROUND(IF('③ パラメータ'!C34="固定",F7+'③ パラメータ'!C28*(1),F7*(1+'③ パラメータ'!E28*(1))),0) | J7: =MIN(100,G7+(INT((1-1)/'③ パラメータ'!C36)+1)*'③ パラメータ'!C35) | K7: =ROUND(IF('③ パラメータ'!C34="固定",E7+'③ パラメータ'!B28*('③ パラメータ'!C32),E7*(1+'③ パラメータ'!D28*('③ パラメータ'!C32))),0) | L7: =ROUND(IF('③ パラメータ'!C34="固定",F7+'③ パラメータ'!C28*('③ パラメータ'!C32),F7*(1+'③ パラメータ'!E28*('③ パラメータ'!C32))),0) | M7: =MIN(100,G7+(INT(('③ パラメータ'!C32-1)/'③ パラメータ'!C36)+1)*'③ パラメータ'!C35) | N7: 終末の進軍 | O7: このACTIVEによる2回の攻撃時、自身のATK+30%。敵へ2回攻撃する。各攻撃の対象は個別に選択できる。このターンの攻撃を消費する。 | P7: 1バトル1回 | Q7: 終末の巨人 | R7: 受ける攻撃ダメージを自身の最大HP5%分だけ軽減する。さらに、スルト以外の味方が戦闘不能になるたび、自身のATK+20%。 | S7: バトル開始時
A8: ロキ | B8: S | C8: 5 | D8: 男性 | E8: 46 | F8: 8 | G8: 84 | H8: =ROUND(IF('③ パラメータ'!C34="固定",E8+'③ パラメータ'!B28*(1),E8*(1+'③ パラメータ'!D28*(1))),0) | I8: =ROUND(IF('③ パラメータ'!C34="固定",F8+'③ パラメータ'!C28*(1),F8*(1+'③ パラメータ'!E28*(1))),0) | J8: =MIN(100,G8+(INT((1-1)/'③ パラメータ'!C36)+1)*'③ パラメータ'!C35) | K8: =ROUND(IF('③ パラメータ'!C34="固定",E8+'③ パラメータ'!B28*('③ パラメータ'!C32),E8*(1+'③ パラメータ'!D28*('③ パラメータ'!C32))),0) | L8: =ROUND(IF('③ パラメータ'!C34="固定",F8+'③ パラメータ'!C28*('③ パラメータ'!C32),F8*(1+'③ パラメータ'!E28*('③ パラメータ'!C32))),0) | M8: =MIN(100,G8+(INT(('③ パラメータ'!C32-1)/'③ パラメータ'!C36)+1)*'③ パラメータ'!C35) | N8: 虚実反転 | O8: 生存している敵1体と味方1体を選択し、両者の現在ATKをラウンド終了まで交換する。 | P8: 制限なし | Q8: 欺瞞の神 | R8: ロキが状態異常を受ける時、その状態異常を無効化し、効果を与えた敵へ同じ状態異常を返す。 | S8: 状態異常を受ける直前
A9: ヨルムンガンド | B9: S | C9: 5 | D9: 男性 | E9: 52 | F9: 7 | G9: 55 | H9: =ROUND(IF('③ パラメータ'!C34="固定",E9+'③ パラメータ'!B28*(1),E9*(1+'③ パラメータ'!D28*(1))),0) | I9: =ROUND(IF('③ パラメータ'!C34="固定",F9+'③ パラメータ'!C28*(1),F9*(1+'③ パラメータ'!E28*(1))),0) | J9: =MIN(100,G9+(INT((1-1)/'③ パラメータ'!C36)+1)*'③ パラメータ'!C35) | K9: =ROUND(IF('③ パラメータ'!C34="固定",E9+'③ パラメータ'!B28*('③ パラメータ'!C32),E9*(1+'③ パラメータ'!D28*('③ パラメータ'!C32))),0) | L9: =ROUND(IF('③ パラメータ'!C34="固定",F9+'③ パラメータ'!C28*('③ パラメータ'!C32),F9*(1+'③ パラメータ'!E28*('③ パラメータ'!C32))),0) | M9: =MIN(100,G9+(INT(('③ パラメータ'!C32-1)/'③ パラメータ'!C36)+1)*'③ パラメータ'!C35) | N9: 世界毒 | O9: 生存している敵全体へ、自身のATK60%のスキルダメージ + 毒（自身のATK30%×2ターン）。このターンの攻撃を消費する。 | P9: 1バトル1回 | Q9: 世界を囲む蛇 | R9: バトル開始時、敵全体のATK-15%。 | S9: バトル開始時
A10: ヘル | B10: S | C10: 5 | D10: 女性 | E10: 58 | F10: 6 | G10: 5 | H10: =ROUND(IF('③ パラメータ'!C34="固定",E10+'③ パラメータ'!B28*(1),E10*(1+'③ パラメータ'!D28*(1))),0) | I10: =ROUND(IF('③ パラメータ'!C34="固定",F10+'③ パラメータ'!C28*(1),F10*(1+'③ パラメータ'!E28*(1))),0) | J10: =MIN(100,G10+(INT((1-1)/'③ パラメータ'!C36)+1)*'③ パラメータ'!C35) | K10: =ROUND(IF('③ パラメータ'!C34="固定",E10+'③ パラメータ'!B28*('③ パラメータ'!C32),E10*(1+'③ パラメータ'!D28*('③ パラメータ'!C32))),0) | L10: =ROUND(IF('③ パラメータ'!C34="固定",F10+'③ パラメータ'!C28*('③ パラメータ'!C32),F10*(1+'③ パラメータ'!E28*('③ パラメータ'!C32))),0) | M10: =MIN(100,G10+(INT(('③ パラメータ'!C32-1)/'③ パラメータ'!C36)+1)*'③ パラメータ'!C35) | N10: 死の宣告 | O10: 敵1体を即座に戦闘不能にする。このターンの攻撃を消費する。 | P10: 1バトル1回 | Q10: 冥府の呼び声 | R10: 味方がバトル中初めて戦闘不能になった時、その使い魔を最大HP30%で蘇生する。 | S10: 誰かが倒れた時
A11: アスモデウス | B11: A | C11: 4 | D11: 男性 | E11: 30 | F11: 10 | G11: 82 | H11: =ROUND(IF('③ パラメータ'!C34="固定",E11+'③ パラメータ'!B27*(1),E11*(1+'③ パラメータ'!D27*(1))),0) | I11: =ROUND(IF('③ パラメータ'!C34="固定",F11+'③ パラメータ'!C27*(1),F11*(1+'③ パラメータ'!E27*(1))),0) | J11: =MIN(100,G11+(INT((1-1)/'③ パラメータ'!C36)+1)*'③ パラメータ'!C35) | K11: =ROUND(IF('③ パラメータ'!C34="固定",E11+'③ パラメータ'!B27*('③ パラメータ'!C32),E11*(1+'③ パラメータ'!D27*('③ パラメータ'!C32))),0) | L11: =ROUND(IF('③ パラメータ'!C34="固定",F11+'③ パラメータ'!C27*('③ パラメータ'!C32),F11*(1+'③ パラメータ'!E27*('③ パラメータ'!C32))),0) | M11: =MIN(100,G11+(INT(('③ パラメータ'!C32-1)/'③ パラメータ'!C36)+1)*'③ パラメータ'!C35) | N11: — | O11: — | P11: — | Q11: 色欲の権能 | R11: バトル開始時、味方全員のATK+15%。 | S11: バトル開始時
A12: マモン | B12: A | C12: 4 | D12: 男性 | E12: 31 | F12: 10 | G12: 68 | H12: =ROUND(IF('③ パラメータ'!C34="固定",E12+'③ パラメータ'!B27*(1),E12*(1+'③ パラメータ'!D27*(1))),0) | I12: =ROUND(IF('③ パラメータ'!C34="固定",F12+'③ パラメータ'!C27*(1),F12*(1+'③ パラメータ'!E27*(1))),0) | J12: =MIN(100,G12+(INT((1-1)/'③ パラメータ'!C36)+1)*'③ パラメータ'!C35) | K12: =ROUND(IF('③ パラメータ'!C34="固定",E12+'③ パラメータ'!B27*('③ パラメータ'!C32),E12*(1+'③ パラメータ'!D27*('③ パラメータ'!C32))),0) | L12: =ROUND(IF('③ パラメータ'!C34="固定",F12+'③ パラメータ'!C27*('③ パラメータ'!C32),F12*(1+'③ パラメータ'!E27*('③ パラメータ'!C32))),0) | M12: =MIN(100,G12+(INT(('③ パラメータ'!C32-1)/'③ パラメータ'!C36)+1)*'③ パラメータ'!C35) | N12: 強欲 | O12: 敵1体のATK-25%。さらに自身のATK+20%。両方ともラウンド終了まで継続する。 | P12: 制限なし | Q12: — | R12: — | S12: —
A13: アバドン | B13: A | C13: 4 | D13: 男性 | E13: 32 | F13: 10 | G13: 52 | H13: =ROUND(IF('③ パラメータ'!C34="固定",E13+'③ パラメータ'!B27*(1),E13*(1+'③ パラメータ'!D27*(1))),0) | I13: =ROUND(IF('③ パラメータ'!C34="固定",F13+'③ パラメータ'!C27*(1),F13*(1+'③ パラメータ'!E27*(1))),0) | J13: =MIN(100,G13+(INT((1-1)/'③ パラメータ'!C36)+1)*'③ パラメータ'!C35) | K13: =ROUND(IF('③ パラメータ'!C34="固定",E13+'③ パラメータ'!B27*('③ パラメータ'!C32),E13*(1+'③ パラメータ'!D27*('③ パラメータ'!C32))),0) | L13: =ROUND(IF('③ パラメータ'!C34="固定",F13+'③ パラメータ'!C27*('③ パラメータ'!C32),F13*(1+'③ パラメータ'!E27*('③ パラメータ'!C32))),0) | M13: =MIN(100,G13+(INT(('③ パラメータ'!C32-1)/'③ パラメータ'!C36)+1)*'③ パラメータ'!C35) | N13: 奈落崩壊 | O13: 生存している敵全体へ、自身のATK45%のスキルダメージ。このターンの攻撃を消費する。 | P13: 制限なし | Q13: — | R13: — | S13: —
A14: サタン | B14: A | C14: 4 | D14: 男性 | E14: 36 | F14: 9 | G14: 46 | H14: =ROUND(IF('③ パラメータ'!C34="固定",E14+'③ パラメータ'!B27*(1),E14*(1+'③ パラメータ'!D27*(1))),0) | I14: =ROUND(IF('③ パラメータ'!C34="固定",F14+'③ パラメータ'!C27*(1),F14*(1+'③ パラメータ'!E27*(1))),0) | J14: =MIN(100,G14+(INT((1-1)/'③ パラメータ'!C36)+1)*'③ パラメータ'!C35) | K14: =ROUND(IF('③ パラメータ'!C34="固定",E14+'③ パラメータ'!B27*('③ パラメータ'!C32),E14*(1+'③ パラメータ'!D27*('③ パラメータ'!C32))),0) | L14: =ROUND(IF('③ パラメータ'!C34="固定",F14+'③ パラメータ'!C27*('③ パラメータ'!C32),F14*(1+'③ パラメータ'!E27*('③ パラメータ'!C32))),0) | M14: =MIN(100,G14+(INT(('③ パラメータ'!C32-1)/'③ パラメータ'!C36)+1)*'③ パラメータ'!C35) | N14: 憤怒の解放 | O14: 味方全員に付与されているデバフをすべて解除する。状態異常は解除しない。 | P14: 1バトル1回 | Q14: — | R14: — | S14: —
A15: ニーズヘッグ | B15: A | C15: 4 | D15: 男性 | E15: 36 | F15: 9 | G15: 50 | H15: =ROUND(IF('③ パラメータ'!C34="固定",E15+'③ パラメータ'!B27*(1),E15*(1+'③ パラメータ'!D27*(1))),0) | I15: =ROUND(IF('③ パラメータ'!C34="固定",F15+'③ パラメータ'!C27*(1),F15*(1+'③ パラメータ'!E27*(1))),0) | J15: =MIN(100,G15+(INT((1-1)/'③ パラメータ'!C36)+1)*'③ パラメータ'!C35) | K15: =ROUND(IF('③ パラメータ'!C34="固定",E15+'③ パラメータ'!B27*('③ パラメータ'!C32),E15*(1+'③ パラメータ'!D27*('③ パラメータ'!C32))),0) | L15: =ROUND(IF('③ パラメータ'!C34="固定",F15+'③ パラメータ'!C27*('③ パラメータ'!C32),F15*(1+'③ パラメータ'!E27*('③ パラメータ'!C32))),0) | M15: =MIN(100,G15+(INT(('③ パラメータ'!C32-1)/'③ パラメータ'!C36)+1)*'③ パラメータ'!C35) | N15: — | O15: — | P15: — | Q15: 根喰らい | R15: 攻撃ダメージを与えた敵に回復阻害デバフ（2ターン）を付与する。対象はHPを回復できず、蘇生もできない。 | S15: after_attack
A16: ベリアル | B16: A | C16: 4 | D16: 男性 | E16: 34 | F16: 9 | G16: 92 | H16: =ROUND(IF('③ パラメータ'!C34="固定",E16+'③ パラメータ'!B27*(1),E16*(1+'③ パラメータ'!D27*(1))),0) | I16: =ROUND(IF('③ パラメータ'!C34="固定",F16+'③ パラメータ'!C27*(1),F16*(1+'③ パラメータ'!E27*(1))),0) | J16: =MIN(100,G16+(INT((1-1)/'③ パラメータ'!C36)+1)*'③ パラメータ'!C35) | K16: =ROUND(IF('③ パラメータ'!C34="固定",E16+'③ パラメータ'!B27*('③ パラメータ'!C32),E16*(1+'③ パラメータ'!D27*('③ パラメータ'!C32))),0) | L16: =ROUND(IF('③ パラメータ'!C34="固定",F16+'③ パラメータ'!C27*('③ パラメータ'!C32),F16*(1+'③ パラメータ'!E27*('③ パラメータ'!C32))),0) | M16: =MIN(100,G16+(INT(('③ パラメータ'!C32-1)/'③ パラメータ'!C36)+1)*'③ パラメータ'!C35) | N16: — | O16: — | P16: — | Q16: 魔王の先見 | R16: 味方がバトル中初めて行動不能になる時、その行動不能を無効化する。 | S16: 状態異常を受ける直前
A17: キュウビ | B17: A | C17: 4 | D17: 女性 | E17: 34 | F17: 9 | G17: 97 | H17: =ROUND(IF('③ パラメータ'!C34="固定",E17+'③ パラメータ'!B27*(1),E17*(1+'③ パラメータ'!D27*(1))),0) | I17: =ROUND(IF('③ パラメータ'!C34="固定",F17+'③ パラメータ'!C27*(1),F17*(1+'③ パラメータ'!E27*(1))),0) | J17: =MIN(100,G17+(INT((1-1)/'③ パラメータ'!C36)+1)*'③ パラメータ'!C35) | K17: =ROUND(IF('③ パラメータ'!C34="固定",E17+'③ パラメータ'!B27*('③ パラメータ'!C32),E17*(1+'③ パラメータ'!D27*('③ パラメータ'!C32))),0) | L17: =ROUND(IF('③ パラメータ'!C34="固定",F17+'③ パラメータ'!C27*('③ パラメータ'!C32),F17*(1+'③ パラメータ'!E27*('③ パラメータ'!C32))),0) | M17: =MIN(100,G17+(INT(('③ パラメータ'!C32-1)/'③ パラメータ'!C36)+1)*'③ パラメータ'!C35) | N17: 妖狐幻術 | O17: 敵1体のSPD-20%（2ターン）。 | P17: 制限なし | Q17: — | R17: — | S17: —
A18: リリス | B18: A | C18: 4 | D18: 女性 | E18: 35 | F18: 9 | G18: 74 | H18: =ROUND(IF('③ パラメータ'!C34="固定",E18+'③ パラメータ'!B27*(1),E18*(1+'③ パラメータ'!D27*(1))),0) | I18: =ROUND(IF('③ パラメータ'!C34="固定",F18+'③ パラメータ'!C27*(1),F18*(1+'③ パラメータ'!E27*(1))),0) | J18: =MIN(100,G18+(INT((1-1)/'③ パラメータ'!C36)+1)*'③ パラメータ'!C35) | K18: =ROUND(IF('③ パラメータ'!C34="固定",E18+'③ パラメータ'!B27*('③ パラメータ'!C32),E18*(1+'③ パラメータ'!D27*('③ パラメータ'!C32))),0) | L18: =ROUND(IF('③ パラメータ'!C34="固定",F18+'③ パラメータ'!C27*('③ パラメータ'!C32),F18*(1+'③ パラメータ'!E27*('③ パラメータ'!C32))),0) | M18: =MIN(100,G18+(INT(('③ パラメータ'!C32-1)/'③ パラメータ'!C36)+1)*'③ パラメータ'!C35) | N18: — | O18: — | P18: — | Q18: 夜の誘惑 | R18: バトル開始時、男性の敵全体のATK-25%。 | S18: バトル開始時
A19: フェニックス | B19: A | C19: 4 | D19: なし | E19: 35 | F19: 9 | G19: 64 | H19: =ROUND(IF('③ パラメータ'!C34="固定",E19+'③ パラメータ'!B27*(1),E19*(1+'③ パラメータ'!D27*(1))),0) | I19: =ROUND(IF('③ パラメータ'!C34="固定",F19+'③ パラメータ'!C27*(1),F19*(1+'③ パラメータ'!E27*(1))),0) | J19: =MIN(100,G19+(INT((1-1)/'③ パラメータ'!C36)+1)*'③ パラメータ'!C35) | K19: =ROUND(IF('③ パラメータ'!C34="固定",E19+'③ パラメータ'!B27*('③ パラメータ'!C32),E19*(1+'③ パラメータ'!D27*('③ パラメータ'!C32))),0) | L19: =ROUND(IF('③ パラメータ'!C34="固定",F19+'③ パラメータ'!C27*('③ パラメータ'!C32),F19*(1+'③ パラメータ'!E27*('③ パラメータ'!C32))),0) | M19: =MIN(100,G19+(INT(('③ パラメータ'!C32-1)/'③ パラメータ'!C36)+1)*'③ パラメータ'!C35) | N19: 再誕の炎 | O19: 戦闘不能の味方1体を最大HP50%で蘇生する。このターンの攻撃を消費する。 | P19: 1バトル1回 | Q19: — | R19: — | S19: —
A20: ルシファー | B20: A | C20: 4 | D20: 男性 | E20: 38 | F20: 8 | G20: 90 | H20: =ROUND(IF('③ パラメータ'!C34="固定",E20+'③ パラメータ'!B27*(1),E20*(1+'③ パラメータ'!D27*(1))),0) | I20: =ROUND(IF('③ パラメータ'!C34="固定",F20+'③ パラメータ'!C27*(1),F20*(1+'③ パラメータ'!E27*(1))),0) | J20: =MIN(100,G20+(INT((1-1)/'③ パラメータ'!C36)+1)*'③ パラメータ'!C35) | K20: =ROUND(IF('③ パラメータ'!C34="固定",E20+'③ パラメータ'!B27*('③ パラメータ'!C32),E20*(1+'③ パラメータ'!D27*('③ パラメータ'!C32))),0) | L20: =ROUND(IF('③ パラメータ'!C34="固定",F20+'③ パラメータ'!C27*('③ パラメータ'!C32),F20*(1+'③ パラメータ'!E27*('③ パラメータ'!C32))),0) | M20: =MIN(100,G20+(INT(('③ パラメータ'!C32-1)/'③ パラメータ'!C36)+1)*'③ パラメータ'!C35) | N20: 明星の加護 | O20: 味方1体は状態異常を受けない（2ターン）。すでに受けている状態異常は解除しない。 | P20: 1バトル1回 | Q20: — | R20: — | S20: —
A21: ベルゼブブ | B21: A | C21: 4 | D21: 男性 | E21: 40 | F21: 8 | G21: 58 | H21: =ROUND(IF('③ パラメータ'!C34="固定",E21+'③ パラメータ'!B27*(1),E21*(1+'③ パラメータ'!D27*(1))),0) | I21: =ROUND(IF('③ パラメータ'!C34="固定",F21+'③ パラメータ'!C27*(1),F21*(1+'③ パラメータ'!E27*(1))),0) | J21: =MIN(100,G21+(INT((1-1)/'③ パラメータ'!C36)+1)*'③ パラメータ'!C35) | K21: =ROUND(IF('③ パラメータ'!C34="固定",E21+'③ パラメータ'!B27*('③ パラメータ'!C32),E21*(1+'③ パラメータ'!D27*('③ パラメータ'!C32))),0) | L21: =ROUND(IF('③ パラメータ'!C34="固定",F21+'③ パラメータ'!C27*('③ パラメータ'!C32),F21*(1+'③ パラメータ'!E27*('③ パラメータ'!C32))),0) | M21: =MIN(100,G21+(INT(('③ パラメータ'!C32-1)/'③ パラメータ'!C36)+1)*'③ パラメータ'!C35) | N21: — | O21: — | P21: — | Q21: 蠅王の瘴気 | R21: バトル開始時、敵全体に毒（自身のATK40%×2ターン）を付与する。 | S21: バトル開始時
A22: ベルフェゴール | B22: A | C22: 4 | D22: 男性 | E22: 41 | F22: 8 | G22: 24 | H22: =ROUND(IF('③ パラメータ'!C34="固定",E22+'③ パラメータ'!B27*(1),E22*(1+'③ パラメータ'!D27*(1))),0) | I22: =ROUND(IF('③ パラメータ'!C34="固定",F22+'③ パラメータ'!C27*(1),F22*(1+'③ パラメータ'!E27*(1))),0) | J22: =MIN(100,G22+(INT((1-1)/'③ パラメータ'!C36)+1)*'③ パラメータ'!C35) | K22: =ROUND(IF('③ パラメータ'!C34="固定",E22+'③ パラメータ'!B27*('③ パラメータ'!C32),E22*(1+'③ パラメータ'!D27*('③ パラメータ'!C32))),0) | L22: =ROUND(IF('③ パラメータ'!C34="固定",F22+'③ パラメータ'!C27*('③ パラメータ'!C32),F22*(1+'③ パラメータ'!E27*('③ パラメータ'!C32))),0) | M22: =MIN(100,G22+(INT(('③ パラメータ'!C32-1)/'③ パラメータ'!C36)+1)*'③ パラメータ'!C35) | N22: — | O22: — | P22: — | Q22: 怠惰の権能 | R22: 男性の敵へ攻撃ダメージを与えた時、対象を行動不能（1ターン）にする。 | S22: after_attack
A23: アスタロト | B23: A | C23: 4 | D23: 男性 | E23: 40 | F23: 8 | G23: 56 | H23: =ROUND(IF('③ パラメータ'!C34="固定",E23+'③ パラメータ'!B27*(1),E23*(1+'③ パラメータ'!D27*(1))),0) | I23: =ROUND(IF('③ パラメータ'!C34="固定",F23+'③ パラメータ'!C27*(1),F23*(1+'③ パラメータ'!E27*(1))),0) | J23: =MIN(100,G23+(INT((1-1)/'③ パラメータ'!C36)+1)*'③ パラメータ'!C35) | K23: =ROUND(IF('③ パラメータ'!C34="固定",E23+'③ パラメータ'!B27*('③ パラメータ'!C32),E23*(1+'③ パラメータ'!D27*('③ パラメータ'!C32))),0) | L23: =ROUND(IF('③ パラメータ'!C34="固定",F23+'③ パラメータ'!C27*('③ パラメータ'!C32),F23*(1+'③ パラメータ'!E27*('③ パラメータ'!C32))),0) | M23: =MIN(100,G23+(INT(('③ パラメータ'!C32-1)/'③ パラメータ'!C36)+1)*'③ パラメータ'!C35) | N23: 魔王の叡智 | O23: 味方全員に付与されている状態異常をすべて解除する。デバフは解除しない。 | P23: 1バトル1回 | Q23: — | R23: — | S23: —
A24: ファフニール | B24: A | C24: 4 | D24: 男性 | E24: 45 | F24: 7 | G24: 30 | H24: =ROUND(IF('③ パラメータ'!C34="固定",E24+'③ パラメータ'!B27*(1),E24*(1+'③ パラメータ'!D27*(1))),0) | I24: =ROUND(IF('③ パラメータ'!C34="固定",F24+'③ パラメータ'!C27*(1),F24*(1+'③ パラメータ'!E27*(1))),0) | J24: =MIN(100,G24+(INT((1-1)/'③ パラメータ'!C36)+1)*'③ パラメータ'!C35) | K24: =ROUND(IF('③ パラメータ'!C34="固定",E24+'③ パラメータ'!B27*('③ パラメータ'!C32),E24*(1+'③ パラメータ'!D27*('③ パラメータ'!C32))),0) | L24: =ROUND(IF('③ パラメータ'!C34="固定",F24+'③ パラメータ'!C27*('③ パラメータ'!C32),F24*(1+'③ パラメータ'!E27*('③ パラメータ'!C32))),0) | M24: =MIN(100,G24+(INT(('③ パラメータ'!C32-1)/'③ パラメータ'!C36)+1)*'③ パラメータ'!C35) | N24: 黄金の加護 | O24: 味方1体のHPを、その使い魔の最大HP65%分回復する。 | P24: 1バトル1回 | Q24: — | R24: — | S24: —
A25: レヴィアタン | B25: A | C25: 4 | D25: なし | E25: 49 | F25: 6 | G25: 27 | H25: =ROUND(IF('③ パラメータ'!C34="固定",E25+'③ パラメータ'!B27*(1),E25*(1+'③ パラメータ'!D27*(1))),0) | I25: =ROUND(IF('③ パラメータ'!C34="固定",F25+'③ パラメータ'!C27*(1),F25*(1+'③ パラメータ'!E27*(1))),0) | J25: =MIN(100,G25+(INT((1-1)/'③ パラメータ'!C36)+1)*'③ パラメータ'!C35) | K25: =ROUND(IF('③ パラメータ'!C34="固定",E25+'③ パラメータ'!B27*('③ パラメータ'!C32),E25*(1+'③ パラメータ'!D27*('③ パラメータ'!C32))),0) | L25: =ROUND(IF('③ パラメータ'!C34="固定",F25+'③ パラメータ'!C27*('③ パラメータ'!C32),F25*(1+'③ パラメータ'!E27*('③ パラメータ'!C32))),0) | M25: =MIN(100,G25+(INT(('③ パラメータ'!C32-1)/'③ パラメータ'!C36)+1)*'③ パラメータ'!C35) | N25: 深海の威圧 | O25: 敵全体を挑発（1ターン）する。挑発が強制するのは通常攻撃のみ。 | P25: 1バトル1回 | Q25: — | R25: — | S25: —
A26: サイクロプス | B26: B | C26: 3 | D26: 男性 | E26: 25 | F26: 10 | G26: 26 | H26: =ROUND(IF('③ パラメータ'!C34="固定",E26+'③ パラメータ'!B26*(1),E26*(1+'③ パラメータ'!D26*(1))),0) | I26: =ROUND(IF('③ パラメータ'!C34="固定",F26+'③ パラメータ'!C26*(1),F26*(1+'③ パラメータ'!E26*(1))),0) | J26: =MIN(100,G26+(INT((1-1)/'③ パラメータ'!C36)+1)*'③ パラメータ'!C35) | K26: =ROUND(IF('③ パラメータ'!C34="固定",E26+'③ パラメータ'!B26*('③ パラメータ'!C32),E26*(1+'③ パラメータ'!D26*('③ パラメータ'!C32))),0) | L26: =ROUND(IF('③ パラメータ'!C34="固定",F26+'③ パラメータ'!C26*('③ パラメータ'!C32),F26*(1+'③ パラメータ'!E26*('③ パラメータ'!C32))),0) | M26: =MIN(100,G26+(INT(('③ パラメータ'!C32-1)/'③ パラメータ'!C36)+1)*'③ パラメータ'!C35) | N26: — | O26: — | P26: — | Q26: — | R26: — | S26: —
A27: ガルム | B27: B | C27: 3 | D27: 男性 | E27: 27 | F27: 9 | G27: 69 | H27: =ROUND(IF('③ パラメータ'!C34="固定",E27+'③ パラメータ'!B26*(1),E27*(1+'③ パラメータ'!D26*(1))),0) | I27: =ROUND(IF('③ パラメータ'!C34="固定",F27+'③ パラメータ'!C26*(1),F27*(1+'③ パラメータ'!E26*(1))),0) | J27: =MIN(100,G27+(INT((1-1)/'③ パラメータ'!C36)+1)*'③ パラメータ'!C35) | K27: =ROUND(IF('③ パラメータ'!C34="固定",E27+'③ パラメータ'!B26*('③ パラメータ'!C32),E27*(1+'③ パラメータ'!D26*('③ パラメータ'!C32))),0) | L27: =ROUND(IF('③ パラメータ'!C34="固定",F27+'③ パラメータ'!C26*('③ パラメータ'!C32),F27*(1+'③ パラメータ'!E26*('③ パラメータ'!C32))),0) | M27: =MIN(100,G27+(INT(('③ パラメータ'!C32-1)/'③ パラメータ'!C36)+1)*'③ パラメータ'!C35) | N27: — | O27: — | P27: — | Q27: — | R27: — | S27: —
A28: ケルベロス | B28: B | C28: 3 | D28: 男性 | E28: 24 | F28: 8 | G28: 43 | H28: =ROUND(IF('③ パラメータ'!C34="固定",E28+'③ パラメータ'!B26*(1),E28*(1+'③ パラメータ'!D26*(1))),0) | I28: =ROUND(IF('③ パラメータ'!C34="固定",F28+'③ パラメータ'!C26*(1),F28*(1+'③ パラメータ'!E26*(1))),0) | J28: =MIN(100,G28+(INT((1-1)/'③ パラメータ'!C36)+1)*'③ パラメータ'!C35) | K28: =ROUND(IF('③ パラメータ'!C34="固定",E28+'③ パラメータ'!B26*('③ パラメータ'!C32),E28*(1+'③ パラメータ'!D26*('③ パラメータ'!C32))),0) | L28: =ROUND(IF('③ パラメータ'!C34="固定",F28+'③ パラメータ'!C26*('③ パラメータ'!C32),F28*(1+'③ パラメータ'!E26*('③ パラメータ'!C32))),0) | M28: =MIN(100,G28+(INT(('③ パラメータ'!C32-1)/'③ パラメータ'!C36)+1)*'③ パラメータ'!C35) | N28: — | O28: — | P28: — | Q28: 三頭の狩り | R28: HP50%以下の敵を攻撃する時、その攻撃のみATK+25%。 | S28: before_attack
A29: グリフォン | B29: B | C29: 3 | D29: なし | E29: 30 | F29: 8 | G29: 89 | H29: =ROUND(IF('③ パラメータ'!C34="固定",E29+'③ パラメータ'!B26*(1),E29*(1+'③ パラメータ'!D26*(1))),0) | I29: =ROUND(IF('③ パラメータ'!C34="固定",F29+'③ パラメータ'!C26*(1),F29*(1+'③ パラメータ'!E26*(1))),0) | J29: =MIN(100,G29+(INT((1-1)/'③ パラメータ'!C36)+1)*'③ パラメータ'!C35) | K29: =ROUND(IF('③ パラメータ'!C34="固定",E29+'③ パラメータ'!B26*('③ パラメータ'!C32),E29*(1+'③ パラメータ'!D26*('③ パラメータ'!C32))),0) | L29: =ROUND(IF('③ パラメータ'!C34="固定",F29+'③ パラメータ'!C26*('③ パラメータ'!C32),F29*(1+'③ パラメータ'!E26*('③ パラメータ'!C32))),0) | M29: =MIN(100,G29+(INT(('③ パラメータ'!C32-1)/'③ パラメータ'!C36)+1)*'③ パラメータ'!C35) | N29: — | O29: — | P29: — | Q29: — | R29: — | S29: —
A30: イフリート | B30: B | C30: 3 | D30: 男性 | E30: 24 | F30: 8 | G30: 48 | H30: =ROUND(IF('③ パラメータ'!C34="固定",E30+'③ パラメータ'!B26*(1),E30*(1+'③ パラメータ'!D26*(1))),0) | I30: =ROUND(IF('③ パラメータ'!C34="固定",F30+'③ パラメータ'!C26*(1),F30*(1+'③ パラメータ'!E26*(1))),0) | J30: =MIN(100,G30+(INT((1-1)/'③ パラメータ'!C36)+1)*'③ パラメータ'!C35) | K30: =ROUND(IF('③ パラメータ'!C34="固定",E30+'③ パラメータ'!B26*('③ パラメータ'!C32),E30*(1+'③ パラメータ'!D26*('③ パラメータ'!C32))),0) | L30: =ROUND(IF('③ パラメータ'!C34="固定",F30+'③ パラメータ'!C26*('③ パラメータ'!C32),F30*(1+'③ パラメータ'!E26*('③ パラメータ'!C32))),0) | M30: =MIN(100,G30+(INT(('③ パラメータ'!C32-1)/'③ パラメータ'!C36)+1)*'③ パラメータ'!C35) | N30: 灼熱 | O30: 敵1体へ、自身のATK75%のスキルダメージ。このターンの攻撃を消費する。 | P30: 1バトル1回 | Q30: — | R30: — | S30: —
A31: フレースヴェルグ | B31: B | C31: 3 | D31: 男性 | E31: 26 | F31: 7 | G31: 86 | H31: =ROUND(IF('③ パラメータ'!C34="固定",E31+'③ パラメータ'!B26*(1),E31*(1+'③ パラメータ'!D26*(1))),0) | I31: =ROUND(IF('③ パラメータ'!C34="固定",F31+'③ パラメータ'!C26*(1),F31*(1+'③ パラメータ'!E26*(1))),0) | J31: =MIN(100,G31+(INT((1-1)/'③ パラメータ'!C36)+1)*'③ パラメータ'!C35) | K31: =ROUND(IF('③ パラメータ'!C34="固定",E31+'③ パラメータ'!B26*('③ パラメータ'!C32),E31*(1+'③ パラメータ'!D26*('③ パラメータ'!C32))),0) | L31: =ROUND(IF('③ パラメータ'!C34="固定",F31+'③ パラメータ'!C26*('③ パラメータ'!C32),F31*(1+'③ パラメータ'!E26*('③ パラメータ'!C32))),0) | M31: =MIN(100,G31+(INT(('③ パラメータ'!C32-1)/'③ パラメータ'!C36)+1)*'③ パラメータ'!C35) | N31: — | O31: — | P31: — | Q31: 暴風の翼 | R31: 攻撃ダメージを与えた敵のSPD-5%（1ターン）。 | S31: after_attack
A32: メドゥーサ | B32: B | C32: 3 | D32: 女性 | E32: 27 | F32: 7 | G32: 79 | H32: =ROUND(IF('③ パラメータ'!C34="固定",E32+'③ パラメータ'!B26*(1),E32*(1+'③ パラメータ'!D26*(1))),0) | I32: =ROUND(IF('③ パラメータ'!C34="固定",F32+'③ パラメータ'!C26*(1),F32*(1+'③ パラメータ'!E26*(1))),0) | J32: =MIN(100,G32+(INT((1-1)/'③ パラメータ'!C36)+1)*'③ パラメータ'!C35) | K32: =ROUND(IF('③ パラメータ'!C34="固定",E32+'③ パラメータ'!B26*('③ パラメータ'!C32),E32*(1+'③ パラメータ'!D26*('③ パラメータ'!C32))),0) | L32: =ROUND(IF('③ パラメータ'!C34="固定",F32+'③ パラメータ'!C26*('③ パラメータ'!C32),F32*(1+'③ パラメータ'!E26*('③ パラメータ'!C32))),0) | M32: =MIN(100,G32+(INT(('③ パラメータ'!C32-1)/'③ パラメータ'!C36)+1)*'③ パラメータ'!C35) | N32: 石化の魔眼 | O32: 敵1体を行動不能（1ターン）にする。このターンの攻撃を消費する。 | P32: 1バトル1回 | Q32: — | R32: — | S32: —
A33: ミノタウロス | B33: B | C33: 3 | D33: 男性 | E33: 38 | F33: 7 | G33: 14 | H33: =ROUND(IF('③ パラメータ'!C34="固定",E33+'③ パラメータ'!B26*(1),E33*(1+'③ パラメータ'!D26*(1))),0) | I33: =ROUND(IF('③ パラメータ'!C34="固定",F33+'③ パラメータ'!C26*(1),F33*(1+'③ パラメータ'!E26*(1))),0) | J33: =MIN(100,G33+(INT((1-1)/'③ パラメータ'!C36)+1)*'③ パラメータ'!C35) | K33: =ROUND(IF('③ パラメータ'!C34="固定",E33+'③ パラメータ'!B26*('③ パラメータ'!C32),E33*(1+'③ パラメータ'!D26*('③ パラメータ'!C32))),0) | L33: =ROUND(IF('③ パラメータ'!C34="固定",F33+'③ パラメータ'!C26*('③ パラメータ'!C32),F33*(1+'③ パラメータ'!E26*('③ パラメータ'!C32))),0) | M33: =MIN(100,G33+(INT(('③ パラメータ'!C32-1)/'③ パラメータ'!C36)+1)*'③ パラメータ'!C35) | N33: — | O33: — | P33: — | Q33: — | R33: — | S33: —
A34: キマイラ | B34: B | C34: 3 | D34: 女性 | E34: 27 | F34: 7 | G34: 60 | H34: =ROUND(IF('③ パラメータ'!C34="固定",E34+'③ パラメータ'!B26*(1),E34*(1+'③ パラメータ'!D26*(1))),0) | I34: =ROUND(IF('③ パラメータ'!C34="固定",F34+'③ パラメータ'!C26*(1),F34*(1+'③ パラメータ'!E26*(1))),0) | J34: =MIN(100,G34+(INT((1-1)/'③ パラメータ'!C36)+1)*'③ パラメータ'!C35) | K34: =ROUND(IF('③ パラメータ'!C34="固定",E34+'③ パラメータ'!B26*('③ パラメータ'!C32),E34*(1+'③ パラメータ'!D26*('③ パラメータ'!C32))),0) | L34: =ROUND(IF('③ パラメータ'!C34="固定",F34+'③ パラメータ'!C26*('③ パラメータ'!C32),F34*(1+'③ パラメータ'!E26*('③ パラメータ'!C32))),0) | M34: =MIN(100,G34+(INT(('③ パラメータ'!C32-1)/'③ パラメータ'!C36)+1)*'③ パラメータ'!C35) | N34: — | O34: — | P34: — | Q34: 異形の狩り | R34: 状態異常またはデバフを受けている敵を攻撃する時、その攻撃のみATK+30%。 | S34: before_attack
A35: アザゼル | B35: B | C35: 3 | D35: 男性 | E35: 27 | F35: 7 | G35: 67 | H35: =ROUND(IF('③ パラメータ'!C34="固定",E35+'③ パラメータ'!B26*(1),E35*(1+'③ パラメータ'!D26*(1))),0) | I35: =ROUND(IF('③ パラメータ'!C34="固定",F35+'③ パラメータ'!C26*(1),F35*(1+'③ パラメータ'!E26*(1))),0) | J35: =MIN(100,G35+(INT((1-1)/'③ パラメータ'!C36)+1)*'③ パラメータ'!C35) | K35: =ROUND(IF('③ パラメータ'!C34="固定",E35+'③ パラメータ'!B26*('③ パラメータ'!C32),E35*(1+'③ パラメータ'!D26*('③ パラメータ'!C32))),0) | L35: =ROUND(IF('③ パラメータ'!C34="固定",F35+'③ パラメータ'!C26*('③ パラメータ'!C32),F35*(1+'③ パラメータ'!E26*('③ パラメータ'!C32))),0) | M35: =MIN(100,G35+(INT(('③ パラメータ'!C32-1)/'③ パラメータ'!C36)+1)*'③ パラメータ'!C35) | N35: 堕天の鼓舞 | O35: 味方1体のATK+15%（2ターン）。 | P35: 制限なし | Q35: — | R35: — | S35: —
A36: セイレーン | B36: B | C36: 3 | D36: 女性 | E36: 26 | F36: 7 | G36: 80 | H36: =ROUND(IF('③ パラメータ'!C34="固定",E36+'③ パラメータ'!B26*(1),E36*(1+'③ パラメータ'!D26*(1))),0) | I36: =ROUND(IF('③ パラメータ'!C34="固定",F36+'③ パラメータ'!C26*(1),F36*(1+'③ パラメータ'!E26*(1))),0) | J36: =MIN(100,G36+(INT((1-1)/'③ パラメータ'!C36)+1)*'③ パラメータ'!C35) | K36: =ROUND(IF('③ パラメータ'!C34="固定",E36+'③ パラメータ'!B26*('③ パラメータ'!C32),E36*(1+'③ パラメータ'!D26*('③ パラメータ'!C32))),0) | L36: =ROUND(IF('③ パラメータ'!C34="固定",F36+'③ パラメータ'!C26*('③ パラメータ'!C32),F36*(1+'③ パラメータ'!E26*('③ パラメータ'!C32))),0) | M36: =MIN(100,G36+(INT(('③ パラメータ'!C32-1)/'③ パラメータ'!C36)+1)*'③ パラメータ'!C35) | N36: — | O36: — | P36: — | Q36: 惑わしの歌 | R36: バトル開始時、男性の敵の中で最もATKが高い1体のATK-15%。 | S36: バトル開始時
A37: デュラハン | B37: B | C37: 3 | D37: 男性 | E37: 29 | F37: 7 | G37: 38 | H37: =ROUND(IF('③ パラメータ'!C34="固定",E37+'③ パラメータ'!B26*(1),E37*(1+'③ パラメータ'!D26*(1))),0) | I37: =ROUND(IF('③ パラメータ'!C34="固定",F37+'③ パラメータ'!C26*(1),F37*(1+'③ パラメータ'!E26*(1))),0) | J37: =MIN(100,G37+(INT((1-1)/'③ パラメータ'!C36)+1)*'③ パラメータ'!C35) | K37: =ROUND(IF('③ パラメータ'!C34="固定",E37+'③ パラメータ'!B26*('③ パラメータ'!C32),E37*(1+'③ パラメータ'!D26*('③ パラメータ'!C32))),0) | L37: =ROUND(IF('③ パラメータ'!C34="固定",F37+'③ パラメータ'!C26*('③ パラメータ'!C32),F37*(1+'③ パラメータ'!E26*('③ パラメータ'!C32))),0) | M37: =MIN(100,G37+(INT(('③ パラメータ'!C32-1)/'③ パラメータ'!C36)+1)*'③ パラメータ'!C35) | N37: — | O37: — | P37: — | Q37: 首無し騎士 | R37: 攻撃ダメージによって戦闘不能になる時、最大HP4%で耐える。スキルダメージ・継続ダメージでは発動しない。 | S37: 自分が倒れる直前
A38: バンシー | B38: B | C38: 3 | D38: 女性 | E38: 27 | F38: 7 | G38: 66 | H38: =ROUND(IF('③ パラメータ'!C34="固定",E38+'③ パラメータ'!B26*(1),E38*(1+'③ パラメータ'!D26*(1))),0) | I38: =ROUND(IF('③ パラメータ'!C34="固定",F38+'③ パラメータ'!C26*(1),F38*(1+'③ パラメータ'!E26*(1))),0) | J38: =MIN(100,G38+(INT((1-1)/'③ パラメータ'!C36)+1)*'③ パラメータ'!C35) | K38: =ROUND(IF('③ パラメータ'!C34="固定",E38+'③ パラメータ'!B26*('③ パラメータ'!C32),E38*(1+'③ パラメータ'!D26*('③ パラメータ'!C32))),0) | L38: =ROUND(IF('③ パラメータ'!C34="固定",F38+'③ パラメータ'!C26*('③ パラメータ'!C32),F38*(1+'③ パラメータ'!E26*('③ パラメータ'!C32))),0) | M38: =MIN(100,G38+(INT(('③ パラメータ'!C32-1)/'③ パラメータ'!C36)+1)*'③ パラメータ'!C35) | N38: — | O38: — | P38: — | Q38: 死者の慟哭 | R38: 味方が蘇生した時、その使い魔のHPを、さらに最大HP25%分回復する。 | S38: 蘇生された時
A39: ヒュドラ | B39: B | C39: 3 | D39: 女性 | E39: 32 | F39: 6 | G39: 41 | H39: =ROUND(IF('③ パラメータ'!C34="固定",E39+'③ パラメータ'!B26*(1),E39*(1+'③ パラメータ'!D26*(1))),0) | I39: =ROUND(IF('③ パラメータ'!C34="固定",F39+'③ パラメータ'!C26*(1),F39*(1+'③ パラメータ'!E26*(1))),0) | J39: =MIN(100,G39+(INT((1-1)/'③ パラメータ'!C36)+1)*'③ パラメータ'!C35) | K39: =ROUND(IF('③ パラメータ'!C34="固定",E39+'③ パラメータ'!B26*('③ パラメータ'!C32),E39*(1+'③ パラメータ'!D26*('③ パラメータ'!C32))),0) | L39: =ROUND(IF('③ パラメータ'!C34="固定",F39+'③ パラメータ'!C26*('③ パラメータ'!C32),F39*(1+'③ パラメータ'!E26*('③ パラメータ'!C32))),0) | M39: =MIN(100,G39+(INT(('③ パラメータ'!C32-1)/'③ パラメータ'!C36)+1)*'③ パラメータ'!C35) | N39: — | O39: — | P39: — | Q39: 猛毒増幅 | R39: 敵に毒が付与される時、その毒のダメージ+1、継続ターン+1。同じ毒に対して1回のみ適用。 | S39: バトル開始時
A40: 雪女 | B40: B | C40: 3 | D40: 女性 | E40: 31 | F40: 6 | G40: 72 | H40: =ROUND(IF('③ パラメータ'!C34="固定",E40+'③ パラメータ'!B26*(1),E40*(1+'③ パラメータ'!D26*(1))),0) | I40: =ROUND(IF('③ パラメータ'!C34="固定",F40+'③ パラメータ'!C26*(1),F40*(1+'③ パラメータ'!E26*(1))),0) | J40: =MIN(100,G40+(INT((1-1)/'③ パラメータ'!C36)+1)*'③ パラメータ'!C35) | K40: =ROUND(IF('③ パラメータ'!C34="固定",E40+'③ パラメータ'!B26*('③ パラメータ'!C32),E40*(1+'③ パラメータ'!D26*('③ パラメータ'!C32))),0) | L40: =ROUND(IF('③ パラメータ'!C34="固定",F40+'③ パラメータ'!C26*('③ パラメータ'!C32),F40*(1+'③ パラメータ'!E26*('③ パラメータ'!C32))),0) | M40: =MIN(100,G40+(INT(('③ パラメータ'!C32-1)/'③ パラメータ'!C36)+1)*'③ パラメータ'!C35) | N40: 凍てつく風 | O40: 敵全体のSPD-5%（1ターン）。このターンの攻撃を消費する。 | P40: 制限なし | Q40: — | R40: — | S40: —
...

Sheet ③ パラメータ
A1: ③ パラメータ — 黄色のセルを書き換えてください
A2: このシートの数値だけが計算の入り口です。ほかのシートは全部ここを見ています。
A3: ■ 各ランクの使い魔の数
A4: ランク | B4: 現在 | C4: 試す値 | F4: 説明
A5: Cランク | B5: 10 | C5: 10 | F5: 数を減らすと、同じ使い魔が出やすくなります（＝合成しやすい）
A6: Bランク | B6: 20 | C6: 20
A7: Aランク | B7: 15 | C7: 15
A8: Sランク | B8: 5 | C8: 5
A9: 合計 | B9: =SUM(B5:B8) | C9: =SUM(C5:C8)
A11: ■ ガチャの排出率（単発・千分率。合計を必ず1000にする）
A12: ランク | B12: 現在 | C12: 試す値 | D12: ％ | F12: 説明
A13: Cランク | B13: 450 | C13: 450 | D13: =C13/10
A14: Bランク | B14: 450 | C14: 450 | D14: =C14/10
A15: Aランク | B15: 90 | C15: 90 | D15: =C15/10
A16: Sランク | B16: 10 | C16: 10 | D16: =C16/10
A17: 合計 | B17: =SUM(B13:B16) | C17: =SUM(C13:C16) | F17: =IF(C17=1000,"OK","★合計が1000ではありません")
A19: ■ ガチャ費用
A20: 項目 | B20: 現在 | C20: 試す値 | F20: 説明
A21: 単発の費用（coin） | B21: 30000 | C21: 30000 | F21: 1回引くのにかかるcoin
A23: ■ 合成1回あたりの成長量（固定値・％の両方を書いておけます）
A24: ランク | B24: 固定値 HP | C24: 固定値 ATK | D24: 率 HP | E24: 率 ATK | F24: 説明
A25: Cランク | B25: 0 | C25: 0 | D25: 0.05 | E25: 0.05 | F25: 下の「成長のしかた」で、固定値と率のどちらを使うか選びます
A26: Bランク | B26: 1 | C26: 0 | D26: 0.05 | E26: 0.05 | F26: 率は 0.05＝5%。0にするとそのランクは合成できません
A27: Aランク | B27: 2 | C27: 1 | D27: 0.05 | E27: 0.05
A28: Sランク | B28: 3 | C28: 1 | D28: 0.05 | E28: 0.05
A30: ■ 成長の共通設定
A31: 項目 | B31: 現在 | C31: 試す値 | F31: 説明
A32: 最大レベル | B32: 10 | C32: 10 | F32: 下げると必要な体数が一気に減ります
A33: 1レベルに必要な素材数 | B33: 1 | C33: 1 | F33: 必要な体数 =（最大レベル−1）× この数 ＋ 1
A34: 成長のしかた | B34: 率 | C34: 率 | F34: 「固定」か「率」と入力してください
A35: SPD増加量（1回） | B35: 1 | C35: 1 | F35: SPDは上限100で頭打ちになります
A36: SPDが上がる間隔 | B36: 2 | C36: 2 | F36: 2なら Lv1,3,5,7,9 で上がります
A38: ■ 合成費用
A39: 項目 | B39: 現在 | C39: 試す値 | F39: 説明
A40: 素材1体あたり（売却額比） | B40: 0.5 | C40: 0.5 | F40: 0.5なら売却額の半分。0にすると合成は無料
A42: ■ 売却額（Lv1）
A43: ランク | B43: 現在 | C43: 試す値 | F43: 説明
A44: Cランク | B44: 2000 | C44: 2000 | F44: 合成費用もこの金額を基準に決まります
A45: Bランク | B45: 5000 | C45: 5000
A46: Aランク | B46: 15000 | C46: 15000
...

Sheet ④ ガチャ試算
A1: ④ ガチャ試算 — 単発だけで計算しています
A2: ③パラメータを変えると自動で変わります。10連・保証枠は考慮していません。
A4: ■ 最大レベルに必要な体数
A5: 必要な体数 | B5: =('③ パラメータ'!C32-1)*'③ パラメータ'!C33+1 | H5: （最大レベル−1）× 1レベルの素材数 ＋ 本体1体
A7: ■ ランクごとの試算
A8: ランク | B8: 使い魔の数 | C8: 特定1体が出る確率 | D8: 1体そろえる単発回数 | E8: 最大Lvに必要な単発回数 | F8: ガチャ費用 | G8: 合成費用 | H8: 合計coin
A9: Cランク | B9: ='③ パラメータ'!C5 | C9: =IF('③ パラメータ'!C5=0,0,'③ パラメータ'!C13/1000/'③ パラメータ'!C5) | D9: =IF(C9=0,"—",1/C9) | E9: =IF(C9=0,"—",$B$5/C9) | F9: =IF(C9=0,"—",E9*'③ パラメータ'!C21) | G9: =($B$5-1)*'③ パラメータ'!C44*'③ パラメータ'!C40 | H9: =IF(C9=0,"—",F9+G9)
A10: Bランク | B10: ='③ パラメータ'!C6 | C10: =IF('③ パラメータ'!C6=0,0,'③ パラメータ'!C14/1000/'③ パラメータ'!C6) | D10: =IF(C10=0,"—",1/C10) | E10: =IF(C10=0,"—",$B$5/C10) | F10: =IF(C10=0,"—",E10*'③ パラメータ'!C21) | G10: =($B$5-1)*'③ パラメータ'!C45*'③ パラメータ'!C40 | H10: =IF(C10=0,"—",F10+G10)
A11: Aランク | B11: ='③ パラメータ'!C7 | C11: =IF('③ パラメータ'!C7=0,0,'③ パラメータ'!C15/1000/'③ パラメータ'!C7) | D11: =IF(C11=0,"—",1/C11) | E11: =IF(C11=0,"—",$B$5/C11) | F11: =IF(C11=0,"—",E11*'③ パラメータ'!C21) | G11: =($B$5-1)*'③ パラメータ'!C46*'③ パラメータ'!C40 | H11: =IF(C11=0,"—",F11+G11)
A12: Sランク | B12: ='③ パラメータ'!C8 | C12: =IF('③ パラメータ'!C8=0,0,'③ パラメータ'!C16/1000/'③ パラメータ'!C8) | D12: =IF(C12=0,"—",1/C12) | E12: =IF(C12=0,"—",$B$5/C12) | F12: =IF(C12=0,"—",E12*'③ パラメータ'!C21) | G12: =($B$5-1)*'③ パラメータ'!C47*'③ パラメータ'!C40 | H12: =IF(C12=0,"—",F12+G12)
A14: ■ 参考：1体だけ引きたい場合
A15: ランク | B15: そのランクが出る確率 | C15: 1体出るまでの単発回数 | D15: そのぶんのcoin
A16: Cランク | B16: ='③ パラメータ'!C13/1000 | C16: =IF('③ パラメータ'!C13=0,"—",1000/'③ パラメータ'!C13) | D16: =IF('③ パラメータ'!C13=0,"—",C16*'③ パラメータ'!C21)
A17: Bランク | B17: ='③ パラメータ'!C14/1000 | C17: =IF('③ パラメータ'!C14=0,"—",1000/'③ パラメータ'!C14) | D17: =IF('③ パラメータ'!C14=0,"—",C17*'③ パラメータ'!C21)
A18: Aランク | B18: ='③ パラメータ'!C15/1000 | C18: =IF('③ パラメータ'!C15=0,"—",1000/'③ パラメータ'!C15) | D18: =IF('③ パラメータ'!C15=0,"—",C18*'③ パラメータ'!C21)
A19: Sランク | B19: ='③ パラメータ'!C16/1000 | C19: =IF('③ パラメータ'!C16=0,"—",1000/'③ パラメータ'!C16) | D19: =IF('③ パラメータ'!C16=0,"—",C19*'③ パラメータ'!C21)

Sheet ⑤ 成長試算
A1: ⑤ 成長試算 — ランクごとの平均能力値を Lv1〜Lv10 で並べたもの
A2: 「素の値」はそのランクの平均です。③パラメータの成長設定を変えると全部動きます。
A3: ※ Lv1の時点で既に1回ぶん成長しています（能力値＝素の値×(1+成長率×レベル)）。
A4: ランク | B4: 項目 | C4: 素の値(Lv0) | D4: Lv1 | E4: Lv2 | F4: Lv3 | G4: Lv4 | H4: Lv5 | I4: Lv6 | J4: Lv7 | K4: Lv8 | L4: Lv9 | M4: Lv10 | N4: Lv1→Lv10
A5: Cランク | B5: HP | C5: 25.2 | D5: =IF(1>'③ パラメータ'!C32,"—",ROUND(IF('③ パラメータ'!C34="固定",$C5+'③ パラメータ'!B25*(1),$C5*(1+'③ パラメータ'!D25*(1))),0)) | E5: =IF(2>'③ パラメータ'!C32,"—",ROUND(IF('③ パラメータ'!C34="固定",$C5+'③ パラメータ'!B25*(2),$C5*(1+'③ パラメータ'!D25*(2))),0)) | F5: =IF(3>'③ パラメータ'!C32,"—",ROUND(IF('③ パラメータ'!C34="固定",$C5+'③ パラメータ'!B25*(3),$C5*(1+'③ パラメータ'!D25*(3))),0)) | G5: =IF(4>'③ パラメータ'!C32,"—",ROUND(IF('③ パラメータ'!C34="固定",$C5+'③ パラメータ'!B25*(4),$C5*(1+'③ パラメータ'!D25*(4))),0)) | H5: =IF(5>'③ パラメータ'!C32,"—",ROUND(IF('③ パラメータ'!C34="固定",$C5+'③ パラメータ'!B25*(5),$C5*(1+'③ パラメータ'!D25*(5))),0)) | I5: =IF(6>'③ パラメータ'!C32,"—",ROUND(IF('③ パラメータ'!C34="固定",$C5+'③ パラメータ'!B25*(6),$C5*(1+'③ パラメータ'!D25*(6))),0)) | J5: =IF(7>'③ パラメータ'!C32,"—",ROUND(IF('③ パラメータ'!C34="固定",$C5+'③ パラメータ'!B25*(7),$C5*(1+'③ パラメータ'!D25*(7))),0)) | K5: =IF(8>'③ パラメータ'!C32,"—",ROUND(IF('③ パラメータ'!C34="固定",$C5+'③ パラメータ'!B25*(8),$C5*(1+'③ パラメータ'!D25*(8))),0)) | L5: =IF(9>'③ パラメータ'!C32,"—",ROUND(IF('③ パラメータ'!C34="固定",$C5+'③ パラメータ'!B25*(9),$C5*(1+'③ パラメータ'!D25*(9))),0)) | M5: =IF(10>'③ パラメータ'!C32,"—",ROUND(IF('③ パラメータ'!C34="固定",$C5+'③ パラメータ'!B25*(10),$C5*(1+'③ パラメータ'!D25*(10))),0)) | N5: =IF(M5="—","—",M5/D5)
B6: ATK | C6: 5.7 | D6: =IF(1>'③ パラメータ'!C32,"—",ROUND(IF('③ パラメータ'!C34="固定",$C6+'③ パラメータ'!C25*(1),$C6*(1+'③ パラメータ'!E25*(1))),0)) | E6: =IF(2>'③ パラメータ'!C32,"—",ROUND(IF('③ パラメータ'!C34="固定",$C6+'③ パラメータ'!C25*(2),$C6*(1+'③ パラメータ'!E25*(2))),0)) | F6: =IF(3>'③ パラメータ'!C32,"—",ROUND(IF('③ パラメータ'!C34="固定",$C6+'③ パラメータ'!C25*(3),$C6*(1+'③ パラメータ'!E25*(3))),0)) | G6: =IF(4>'③ パラメータ'!C32,"—",ROUND(IF('③ パラメータ'!C34="固定",$C6+'③ パラメータ'!C25*(4),$C6*(1+'③ パラメータ'!E25*(4))),0)) | H6: =IF(5>'③ パラメータ'!C32,"—",ROUND(IF('③ パラメータ'!C34="固定",$C6+'③ パラメータ'!C25*(5),$C6*(1+'③ パラメータ'!E25*(5))),0)) | I6: =IF(6>'③ パラメータ'!C32,"—",ROUND(IF('③ パラメータ'!C34="固定",$C6+'③ パラメータ'!C25*(6),$C6*(1+'③ パラメータ'!E25*(6))),0)) | J6: =IF(7>'③ パラメータ'!C32,"—",ROUND(IF('③ パラメータ'!C34="固定",$C6+'③ パラメータ'!C25*(7),$C6*(1+'③ パラメータ'!E25*(7))),0)) | K6: =IF(8>'③ パラメータ'!C32,"—",ROUND(IF('③ パラメータ'!C34="固定",$C6+'③ パラメータ'!C25*(8),$C6*(1+'③ パラメータ'!E25*(8))),0)) | L6: =IF(9>'③ パラメータ'!C32,"—",ROUND(IF('③ パラメータ'!C34="固定",$C6+'③ パラメータ'!C25*(9),$C6*(1+'③ パラメータ'!E25*(9))),0)) | M6: =IF(10>'③ パラメータ'!C32,"—",ROUND(IF('③ パラメータ'!C34="固定",$C6+'③ パラメータ'!C25*(10),$C6*(1+'③ パラメータ'!E25*(10))),0)) | N6: =IF(M6="—","—",M6/D6)
B7: SPD | C7: 49 | D7: =IF(1>'③ パラメータ'!C32,"—",MIN(100,$C7+(INT((1-1)/'③ パラメータ'!C36)+1)*'③ パラメータ'!C35)) | E7: =IF(2>'③ パラメータ'!C32,"—",MIN(100,$C7+(INT((2-1)/'③ パラメータ'!C36)+1)*'③ パラメータ'!C35)) | F7: =IF(3>'③ パラメータ'!C32,"—",MIN(100,$C7+(INT((3-1)/'③ パラメータ'!C36)+1)*'③ パラメータ'!C35)) | G7: =IF(4>'③ パラメータ'!C32,"—",MIN(100,$C7+(INT((4-1)/'③ パラメータ'!C36)+1)*'③ パラメータ'!C35)) | H7: =IF(5>'③ パラメータ'!C32,"—",MIN(100,$C7+(INT((5-1)/'③ パラメータ'!C36)+1)*'③ パラメータ'!C35)) | I7: =IF(6>'③ パラメータ'!C32,"—",MIN(100,$C7+(INT((6-1)/'③ パラメータ'!C36)+1)*'③ パラメータ'!C35)) | J7: =IF(7>'③ パラメータ'!C32,"—",MIN(100,$C7+(INT((7-1)/'③ パラメータ'!C36)+1)*'③ パラメータ'!C35)) | K7: =IF(8>'③ パラメータ'!C32,"—",MIN(100,$C7+(INT((8-1)/'③ パラメータ'!C36)+1)*'③ パラメータ'!C35)) | L7: =IF(9>'③ パラメータ'!C32,"—",MIN(100,$C7+(INT((9-1)/'③ パラメータ'!C36)+1)*'③ パラメータ'!C35)) | M7: =IF(10>'③ パラメータ'!C32,"—",MIN(100,$C7+(INT((10-1)/'③ パラメータ'!C36)+1)*'③ パラメータ'!C35)) | N7: =IF(M7="—","—",M7/D7)
A8: Bランク | B8: HP | C8: 29.6 | D8: =IF(1>'③ パラメータ'!C32,"—",ROUND(IF('③ パラメータ'!C34="固定",$C8+'③ パラメータ'!B26*(1),$C8*(1+'③ パラメータ'!D26*(1))),0)) | E8: =IF(2>'③ パラメータ'!C32,"—",ROUND(IF('③ パラメータ'!C34="固定",$C8+'③ パラメータ'!B26*(2),$C8*(1+'③ パラメータ'!D26*(2))),0)) | F8: =IF(3>'③ パラメータ'!C32,"—",ROUND(IF('③ パラメータ'!C34="固定",$C8+'③ パラメータ'!B26*(3),$C8*(1+'③ パラメータ'!D26*(3))),0)) | G8: =IF(4>'③ パラメータ'!C32,"—",ROUND(IF('③ パラメータ'!C34="固定",$C8+'③ パラメータ'!B26*(4),$C8*(1+'③ パラメータ'!D26*(4))),0)) | H8: =IF(5>'③ パラメータ'!C32,"—",ROUND(IF('③ パラメータ'!C34="固定",$C8+'③ パラメータ'!B26*(5),$C8*(1+'③ パラメータ'!D26*(5))),0)) | I8: =IF(6>'③ パラメータ'!C32,"—",ROUND(IF('③ パラメータ'!C34="固定",$C8+'③ パラメータ'!B26*(6),$C8*(1+'③ パラメータ'!D26*(6))),0)) | J8: =IF(7>'③ パラメータ'!C32,"—",ROUND(IF('③ パラメータ'!C34="固定",$C8+'③ パラメータ'!B26*(7),$C8*(1+'③ パラメータ'!D26*(7))),0)) | K8: =IF(8>'③ パラメータ'!C32,"—",ROUND(IF('③ パラメータ'!C34="固定",$C8+'③ パラメータ'!B26*(8),$C8*(1+'③ パラメータ'!D26*(8))),0)) | L8: =IF(9>'③ パラメータ'!C32,"—",ROUND(IF('③ パラメータ'!C34="固定",$C8+'③ パラメータ'!B26*(9),$C8*(1+'③ パラメータ'!D26*(9))),0)) | M8: =IF(10>'③ パラメータ'!C32,"—",ROUND(IF('③ パラメータ'!C34="固定",$C8+'③ パラメータ'!B26*(10),$C8*(1+'③ パラメータ'!D26*(10))),0)) | N8: =IF(M8="—","—",M8/D8)
B9: ATK | C9: 7 | D9: =IF(1>'③ パラメータ'!C32,"—",ROUND(IF('③ パラメータ'!C34="固定",$C9+'③ パラメータ'!C26*(1),$C9*(1+'③ パラメータ'!E26*(1))),0)) | E9: =IF(2>'③ パラメータ'!C32,"—",ROUND(IF('③ パラメータ'!C34="固定",$C9+'③ パラメータ'!C26*(2),$C9*(1+'③ パラメータ'!E26*(2))),0)) | F9: =IF(3>'③ パラメータ'!C32,"—",ROUND(IF('③ パラメータ'!C34="固定",$C9+'③ パラメータ'!C26*(3),$C9*(1+'③ パラメータ'!E26*(3))),0)) | G9: =IF(4>'③ パラメータ'!C32,"—",ROUND(IF('③ パラメータ'!C34="固定",$C9+'③ パラメータ'!C26*(4),$C9*(1+'③ パラメータ'!E26*(4))),0)) | H9: =IF(5>'③ パラメータ'!C32,"—",ROUND(IF('③ パラメータ'!C34="固定",$C9+'③ パラメータ'!C26*(5),$C9*(1+'③ パラメータ'!E26*(5))),0)) | I9: =IF(6>'③ パラメータ'!C32,"—",ROUND(IF('③ パラメータ'!C34="固定",$C9+'③ パラメータ'!C26*(6),$C9*(1+'③ パラメータ'!E26*(6))),0)) | J9: =IF(7>'③ パラメータ'!C32,"—",ROUND(IF('③ パラメータ'!C34="固定",$C9+'③ パラメータ'!C26*(7),$C9*(1+'③ パラメータ'!E26*(7))),0)) | K9: =IF(8>'③ パラメータ'!C32,"—",ROUND(IF('③ パラメータ'!C34="固定",$C9+'③ パラメータ'!C26*(8),$C9*(1+'③ パラメータ'!E26*(8))),0)) | L9: =IF(9>'③ パラメータ'!C32,"—",ROUND(IF('③ パラメータ'!C34="固定",$C9+'③ パラメータ'!C26*(9),$C9*(1+'③ パラメータ'!E26*(9))),0)) | M9: =IF(10>'③ パラメータ'!C32,"—",ROUND(IF('③ パラメータ'!C34="固定",$C9+'③ パラメータ'!C26*(10),$C9*(1+'③ パラメータ'!E26*(10))),0)) | N9: =IF(M9="—","—",M9/D9)
B10: SPD | C10: 55.7 | D10: =IF(1>'③ パラメータ'!C32,"—",MIN(100,$C10+(INT((1-1)/'③ パラメータ'!C36)+1)*'③ パラメータ'!C35)) | E10: =IF(2>'③ パラメータ'!C32,"—",MIN(100,$C10+(INT((2-1)/'③ パラメータ'!C36)+1)*'③ パラメータ'!C35)) | F10: =IF(3>'③ パラメータ'!C32,"—",MIN(100,$C10+(INT((3-1)/'③ パラメータ'!C36)+1)*'③ パラメータ'!C35)) | G10: =IF(4>'③ パラメータ'!C32,"—",MIN(100,$C10+(INT((4-1)/'③ パラメータ'!C36)+1)*'③ パラメータ'!C35)) | H10: =IF(5>'③ パラメータ'!C32,"—",MIN(100,$C10+(INT((5-1)/'③ パラメータ'!C36)+1)*'③ パラメータ'!C35)) | I10: =IF(6>'③ パラメータ'!C32,"—",MIN(100,$C10+(INT((6-1)/'③ パラメータ'!C36)+1)*'③ パラメータ'!C35)) | J10: =IF(7>'③ パラメータ'!C32,"—",MIN(100,$C10+(INT((7-1)/'③ パラメータ'!C36)+1)*'③ パラメータ'!C35)) | K10: =IF(8>'③ パラメータ'!C32,"—",MIN(100,$C10+(INT((8-1)/'③ パラメータ'!C36)+1)*'③ パラメータ'!C35)) | L10: =IF(9>'③ パラメータ'!C32,"—",MIN(100,$C10+(INT((9-1)/'③ パラメータ'!C36)+1)*'③ パラメータ'!C35)) | M10: =IF(10>'③ パラメータ'!C32,"—",MIN(100,$C10+(INT((10-1)/'③ パラメータ'!C36)+1)*'③ パラメータ'!C35)) | N10: =IF(M10="—","—",M10/D10)
A11: Aランク | B11: HP | C11: 37.1 | D11: =IF(1>'③ パラメータ'!C32,"—",ROUND(IF('③ パラメータ'!C34="固定",$C11+'③ パラメータ'!B27*(1),$C11*(1+'③ パラメータ'!D27*(1))),0)) | E11: =IF(2>'③ パラメータ'!C32,"—",ROUND(IF('③ パラメータ'!C34="固定",$C11+'③ パラメータ'!B27*(2),$C11*(1+'③ パラメータ'!D27*(2))),0)) | F11: =IF(3>'③ パラメータ'!C32,"—",ROUND(IF('③ パラメータ'!C34="固定",$C11+'③ パラメータ'!B27*(3),$C11*(1+'③ パラメータ'!D27*(3))),0)) | G11: =IF(4>'③ パラメータ'!C32,"—",ROUND(IF('③ パラメータ'!C34="固定",$C11+'③ パラメータ'!B27*(4),$C11*(1+'③ パラメータ'!D27*(4))),0)) | H11: =IF(5>'③ パラメータ'!C32,"—",ROUND(IF('③ パラメータ'!C34="固定",$C11+'③ パラメータ'!B27*(5),$C11*(1+'③ パラメータ'!D27*(5))),0)) | I11: =IF(6>'③ パラメータ'!C32,"—",ROUND(IF('③ パラメータ'!C34="固定",$C11+'③ パラメータ'!B27*(6),$C11*(1+'③ パラメータ'!D27*(6))),0)) | J11: =IF(7>'③ パラメータ'!C32,"—",ROUND(IF('③ パラメータ'!C34="固定",$C11+'③ パラメータ'!B27*(7),$C11*(1+'③ パラメータ'!D27*(7))),0)) | K11: =IF(8>'③ パラメータ'!C32,"—",ROUND(IF('③ パラメータ'!C34="固定",$C11+'③ パラメータ'!B27*(8),$C11*(1+'③ パラメータ'!D27*(8))),0)) | L11: =IF(9>'③ パラメータ'!C32,"—",ROUND(IF('③ パラメータ'!C34="固定",$C11+'③ パラメータ'!B27*(9),$C11*(1+'③ パラメータ'!D27*(9))),0)) | M11: =IF(10>'③ パラメータ'!C32,"—",ROUND(IF('③ パラメータ'!C34="固定",$C11+'③ パラメータ'!B27*(10),$C11*(1+'③ パラメータ'!D27*(10))),0)) | N11: =IF(M11="—","—",M11/D11)
B12: ATK | C12: 8.6 | D12: =IF(1>'③ パラメータ'!C32,"—",ROUND(IF('③ パラメータ'!C34="固定",$C12+'③ パラメータ'!C27*(1),$C12*(1+'③ パラメータ'!E27*(1))),0)) | E12: =IF(2>'③ パラメータ'!C32,"—",ROUND(IF('③ パラメータ'!C34="固定",$C12+'③ パラメータ'!C27*(2),$C12*(1+'③ パラメータ'!E27*(2))),0)) | F12: =IF(3>'③ パラメータ'!C32,"—",ROUND(IF('③ パラメータ'!C34="固定",$C12+'③ パラメータ'!C27*(3),$C12*(1+'③ パラメータ'!E27*(3))),0)) | G12: =IF(4>'③ パラメータ'!C32,"—",ROUND(IF('③ パラメータ'!C34="固定",$C12+'③ パラメータ'!C27*(4),$C12*(1+'③ パラメータ'!E27*(4))),0)) | H12: =IF(5>'③ パラメータ'!C32,"—",ROUND(IF('③ パラメータ'!C34="固定",$C12+'③ パラメータ'!C27*(5),$C12*(1+'③ パラメータ'!E27*(5))),0)) | I12: =IF(6>'③ パラメータ'!C32,"—",ROUND(IF('③ パラメータ'!C34="固定",$C12+'③ パラメータ'!C27*(6),$C12*(1+'③ パラメータ'!E27*(6))),0)) | J12: =IF(7>'③ パラメータ'!C32,"—",ROUND(IF('③ パラメータ'!C34="固定",$C12+'③ パラメータ'!C27*(7),$C12*(1+'③ パラメータ'!E27*(7))),0)) | K12: =IF(8>'③ パラメータ'!C32,"—",ROUND(IF('③ パラメータ'!C34="固定",$C12+'③ パラメータ'!C27*(8),$C12*(1+'③ パラメータ'!E27*(8))),0)) | L12: =IF(9>'③ パラメータ'!C32,"—",ROUND(IF('③ パラメータ'!C34="固定",$C12+'③ パラメータ'!C27*(9),$C12*(1+'③ パラメータ'!E27*(9))),0)) | M12: =IF(10>'③ パラメータ'!C32,"—",ROUND(IF('③ パラメータ'!C34="固定",$C12+'③ パラメータ'!C27*(10),$C12*(1+'③ パラメータ'!E27*(10))),0)) | N12: =IF(M12="—","—",M12/D12)
B13: SPD | C13: 60.7 | D13: =IF(1>'③ パラメータ'!C32,"—",MIN(100,$C13+(INT((1-1)/'③ パラメータ'!C36)+1)*'③ パラメータ'!C35)) | E13: =IF(2>'③ パラメータ'!C32,"—",MIN(100,$C13+(INT((2-1)/'③ パラメータ'!C36)+1)*'③ パラメータ'!C35)) | F13: =IF(3>'③ パラメータ'!C32,"—",MIN(100,$C13+(INT((3-1)/'③ パラメータ'!C36)+1)*'③ パラメータ'!C35)) | G13: =IF(4>'③ パラメータ'!C32,"—",MIN(100,$C13+(INT((4-1)/'③ パラメータ'!C36)+1)*'③ パラメータ'!C35)) | H13: =IF(5>'③ パラメータ'!C32,"—",MIN(100,$C13+(INT((5-1)/'③ パラメータ'!C36)+1)*'③ パラメータ'!C35)) | I13: =IF(6>'③ パラメータ'!C32,"—",MIN(100,$C13+(INT((6-1)/'③ パラメータ'!C36)+1)*'③ パラメータ'!C35)) | J13: =IF(7>'③ パラメータ'!C32,"—",MIN(100,$C13+(INT((7-1)/'③ パラメータ'!C36)+1)*'③ パラメータ'!C35)) | K13: =IF(8>'③ パラメータ'!C32,"—",MIN(100,$C13+(INT((8-1)/'③ パラメータ'!C36)+1)*'③ パラメータ'!C35)) | L13: =IF(9>'③ パラメータ'!C32,"—",MIN(100,$C13+(INT((9-1)/'③ パラメータ'!C36)+1)*'③ パラメータ'!C35)) | M13: =IF(10>'③ パラメータ'!C32,"—",MIN(100,$C13+(INT((10-1)/'③ パラメータ'!C36)+1)*'③ パラメータ'!C35)) | N13: =IF(M13="—","—",M13/D13)
A14: Sランク | B14: HP | C14: 46.4 | D14: =IF(1>'③ パラメータ'!C32,"—",ROUND(IF('③ パラメータ'!C34="固定",$C14+'③ パラメータ'!B28*(1),$C14*(1+'③ パラメータ'!D28*(1))),0)) | E14: =IF(2>'③ パラメータ'!C32,"—",ROUND(IF('③ パラメータ'!C34="固定",$C14+'③ パラメータ'!B28*(2),$C14*(1+'③ パラメータ'!D28*(2))),0)) | F14: =IF(3>'③ パラメータ'!C32,"—",ROUND(IF('③ パラメータ'!C34="固定",$C14+'③ パラメータ'!B28*(3),$C14*(1+'③ パラメータ'!D28*(3))),0)) | G14: =IF(4>'③ パラメータ'!C32,"—",ROUND(IF('③ パラメータ'!C34="固定",$C14+'③ パラメータ'!B28*(4),$C14*(1+'③ パラメータ'!D28*(4))),0)) | H14: =IF(5>'③ パラメータ'!C32,"—",ROUND(IF('③ パラメータ'!C34="固定",$C14+'③ パラメータ'!B28*(5),$C14*(1+'③ パラメータ'!D28*(5))),0)) | I14: =IF(6>'③ パラメータ'!C32,"—",ROUND(IF('③ パラメータ'!C34="固定",$C14+'③ パラメータ'!B28*(6),$C14*(1+'③ パラメータ'!D28*(6))),0)) | J14: =IF(7>'③ パラメータ'!C32,"—",ROUND(IF('③ パラメータ'!C34="固定",$C14+'③ パラメータ'!B28*(7),$C14*(1+'③ パラメータ'!D28*(7))),0)) | K14: =IF(8>'③ パラメータ'!C32,"—",ROUND(IF('③ パラメータ'!C34="固定",$C14+'③ パラメータ'!B28*(8),$C14*(1+'③ パラメータ'!D28*(8))),0)) | L14: =IF(9>'③ パラメータ'!C32,"—",ROUND(IF('③ パラメータ'!C34="固定",$C14+'③ パラメータ'!B28*(9),$C14*(1+'③ パラメータ'!D28*(9))),0)) | M14: =IF(10>'③ パラメータ'!C32,"—",ROUND(IF('③ パラメータ'!C34="固定",$C14+'③ パラメータ'!B28*(10),$C14*(1+'③ パラメータ'!D28*(10))),0)) | N14: =IF(M14="—","—",M14/D14)
B15: ATK | C15: 8.4 | D15: =IF(1>'③ パラメータ'!C32,"—",ROUND(IF('③ パラメータ'!C34="固定",$C15+'③ パラメータ'!C28*(1),$C15*(1+'③ パラメータ'!E28*(1))),0)) | E15: =IF(2>'③ パラメータ'!C32,"—",ROUND(IF('③ パラメータ'!C34="固定",$C15+'③ パラメータ'!C28*(2),$C15*(1+'③ パラメータ'!E28*(2))),0)) | F15: =IF(3>'③ パラメータ'!C32,"—",ROUND(IF('③ パラメータ'!C34="固定",$C15+'③ パラメータ'!C28*(3),$C15*(1+'③ パラメータ'!E28*(3))),0)) | G15: =IF(4>'③ パラメータ'!C32,"—",ROUND(IF('③ パラメータ'!C34="固定",$C15+'③ パラメータ'!C28*(4),$C15*(1+'③ パラメータ'!E28*(4))),0)) | H15: =IF(5>'③ パラメータ'!C32,"—",ROUND(IF('③ パラメータ'!C34="固定",$C15+'③ パラメータ'!C28*(5),$C15*(1+'③ パラメータ'!E28*(5))),0)) | I15: =IF(6>'③ パラメータ'!C32,"—",ROUND(IF('③ パラメータ'!C34="固定",$C15+'③ パラメータ'!C28*(6),$C15*(1+'③ パラメータ'!E28*(6))),0)) | J15: =IF(7>'③ パラメータ'!C32,"—",ROUND(IF('③ パラメータ'!C34="固定",$C15+'③ パラメータ'!C28*(7),$C15*(1+'③ パラメータ'!E28*(7))),0)) | K15: =IF(8>'③ パラメータ'!C32,"—",ROUND(IF('③ パラメータ'!C34="固定",$C15+'③ パラメータ'!C28*(8),$C15*(1+'③ パラメータ'!E28*(8))),0)) | L15: =IF(9>'③ パラメータ'!C32,"—",ROUND(IF('③ パラメータ'!C34="固定",$C15+'③ パラメータ'!C28*(9),$C15*(1+'③ パラメータ'!E28*(9))),0)) | M15: =IF(10>'③ パラメータ'!C32,"—",ROUND(IF('③ パラメータ'!C34="固定",$C15+'③ パラメータ'!C28*(10),$C15*(1+'③ パラメータ'!E28*(10))),0)) | N15: =IF(M15="—","—",M15/D15)
B16: SPD | C16: 51.4 | D16: =IF(1>'③ パラメータ'!C32,"—",MIN(100,$C16+(INT((1-1)/'③ パラメータ'!C36)+1)*'③ パラメータ'!C35)) | E16: =IF(2>'③ パラメータ'!C32,"—",MIN(100,$C16+(INT((2-1)/'③ パラメータ'!C36)+1)*'③ パラメータ'!C35)) | F16: =IF(3>'③ パラメータ'!C32,"—",MIN(100,$C16+(INT((3-1)/'③ パラメータ'!C36)+1)*'③ パラメータ'!C35)) | G16: =IF(4>'③ パラメータ'!C32,"—",MIN(100,$C16+(INT((4-1)/'③ パラメータ'!C36)+1)*'③ パラメータ'!C35)) | H16: =IF(5>'③ パラメータ'!C32,"—",MIN(100,$C16+(INT((5-1)/'③ パラメータ'!C36)+1)*'③ パラメータ'!C35)) | I16: =IF(6>'③ パラメータ'!C32,"—",MIN(100,$C16+(INT((6-1)/'③ パラメータ'!C36)+1)*'③ パラメータ'!C35)) | J16: =IF(7>'③ パラメータ'!C32,"—",MIN(100,$C16+(INT((7-1)/'③ パラメータ'!C36)+1)*'③ パラメータ'!C35)) | K16: =IF(8>'③ パラメータ'!C32,"—",MIN(100,$C16+(INT((8-1)/'③ パラメータ'!C36)+1)*'③ パラメータ'!C35)) | L16: =IF(9>'③ パラメータ'!C32,"—",MIN(100,$C16+(INT((9-1)/'③ パラメータ'!C36)+1)*'③ パラメータ'!C35)) | M16: =IF(10>'③ パラメータ'!C32,"—",MIN(100,$C16+(INT((10-1)/'③ パラメータ'!C36)+1)*'③ パラメータ'!C35)) | N16: =IF(M16="—","—",M16/D16)
A18: ■ 見るときのポイント
A19: ・ATKの素の値は4〜11しかありません。固定で+1すると1回で10〜25%増える計算になります。
A20: ・SはAよりATKもSPDも低めです（S:ATK8.4/SPD51 A:ATK8.6/SPD61）。SはHPとスキルとCOSTで差がついています。
A21: ・SPDは上限100で頭打ちになります。もともと速い使い魔ほど伸びしろが小さくなります。
A22: ・スキルはATK・最大HPの割合で効くため、能力値を上げるとスキル威力も一緒に上がります。

Sheet ⑥ デッキ試算
A1: ⑥ デッキ試算 — 合計COST20以内の編成と、その平均ステータス
A2: ランクの組み合わせごとに、⑤成長試算の平均能力値を足し合わせています。
A3: 「合計」は5体ぶんの合計、「平均」は1体あたりです。SPDは平均で見てください。
A5: S | B5: A | C5: B | D5: C | E5: 体数 | F5: COST | G5: Lv1 HP計 | H5: Lv1 ATK計 | I5: Lv1 SPD平均 | J5: Lv10 HP計 | K5: Lv10 ATK計 | L5: Lv10 SPD平均 | M5: 備考
A6: 3 | B6: 0 | C6: 1 | D6: 1 | E6: 5 | F6: 20 | G6: =A6*'⑤ 成長試算'!D14+B6*'⑤ 成長試算'!D11+C6*'⑤ 成長試算'!D8+D6*'⑤ 成長試算'!D5 | H6: =A6*'⑤ 成長試算'!D15+B6*'⑤ 成長試算'!D12+C6*'⑤ 成長試算'!D9+D6*'⑤ 成長試算'!D6 | I6: =(A6*'⑤ 成長試算'!D16+B6*'⑤ 成長試算'!D13+C6*'⑤ 成長試算'!D10+D6*'⑤ 成長試算'!D7)/E6 | J6: =IF('⑤ 成長試算'!M14="—","—",A6*'⑤ 成長試算'!M14+B6*'⑤ 成長試算'!M11+C6*'⑤ 成長試算'!M8+D6*'⑤ 成長試算'!M5) | K6: =IF('⑤ 成長試算'!M15="—","—",A6*'⑤ 成長試算'!M15+B6*'⑤ 成長試算'!M12+C6*'⑤ 成長試算'!M9+D6*'⑤ 成長試算'!M6) | L6: =IF('⑤ 成長試算'!M16="—","—",(A6*'⑤ 成長試算'!M16+B6*'⑤ 成長試算'!M13+C6*'⑤ 成長試算'!M10+D6*'⑤ 成長試算'!M7)/E6) | M6: COST上限ぴったり
A7: 2 | B7: 2 | C7: 0 | D7: 1 | E7: 5 | F7: 20 | G7: =A7*'⑤ 成長試算'!D14+B7*'⑤ 成長試算'!D11+C7*'⑤ 成長試算'!D8+D7*'⑤ 成長試算'!D5 | H7: =A7*'⑤ 成長試算'!D15+B7*'⑤ 成長試算'!D12+C7*'⑤ 成長試算'!D9+D7*'⑤ 成長試算'!D6 | I7: =(A7*'⑤ 成長試算'!D16+B7*'⑤ 成長試算'!D13+C7*'⑤ 成長試算'!D10+D7*'⑤ 成長試算'!D7)/E7 | J7: =IF('⑤ 成長試算'!M14="—","—",A7*'⑤ 成長試算'!M14+B7*'⑤ 成長試算'!M11+C7*'⑤ 成長試算'!M8+D7*'⑤ 成長試算'!M5) | K7: =IF('⑤ 成長試算'!M15="—","—",A7*'⑤ 成長試算'!M15+B7*'⑤ 成長試算'!M12+C7*'⑤ 成長試算'!M9+D7*'⑤ 成長試算'!M6) | L7: =IF('⑤ 成長試算'!M16="—","—",(A7*'⑤ 成長試算'!M16+B7*'⑤ 成長試算'!M13+C7*'⑤ 成長試算'!M10+D7*'⑤ 成長試算'!M7)/E7) | M7: COST上限ぴったり
A8: 2 | B8: 1 | C8: 2 | D8: 0 | E8: 5 | F8: 20 | G8: =A8*'⑤ 成長試算'!D14+B8*'⑤ 成長試算'!D11+C8*'⑤ 成長試算'!D8+D8*'⑤ 成長試算'!D5 | H8: =A8*'⑤ 成長試算'!D15+B8*'⑤ 成長試算'!D12+C8*'⑤ 成長試算'!D9+D8*'⑤ 成長試算'!D6 | I8: =(A8*'⑤ 成長試算'!D16+B8*'⑤ 成長試算'!D13+C8*'⑤ 成長試算'!D10+D8*'⑤ 成長試算'!D7)/E8 | J8: =IF('⑤ 成長試算'!M14="—","—",A8*'⑤ 成長試算'!M14+B8*'⑤ 成長試算'!M11+C8*'⑤ 成長試算'!M8+D8*'⑤ 成長試算'!M5) | K8: =IF('⑤ 成長試算'!M15="—","—",A8*'⑤ 成長試算'!M15+B8*'⑤ 成長試算'!M12+C8*'⑤ 成長試算'!M9+D8*'⑤ 成長試算'!M6) | L8: =IF('⑤ 成長試算'!M16="—","—",(A8*'⑤ 成長試算'!M16+B8*'⑤ 成長試算'!M13+C8*'⑤ 成長試算'!M10+D8*'⑤ 成長試算'!M7)/E8) | M8: COST上限ぴったり
A9: 1 | B9: 3 | C9: 1 | D9: 0 | E9: 5 | F9: 20 | G9: =A9*'⑤ 成長試算'!D14+B9*'⑤ 成長試算'!D11+C9*'⑤ 成長試算'!D8+D9*'⑤ 成長試算'!D5 | H9: =A9*'⑤ 成長試算'!D15+B9*'⑤ 成長試算'!D12+C9*'⑤ 成長試算'!D9+D9*'⑤ 成長試算'!D6 | I9: =(A9*'⑤ 成長試算'!D16+B9*'⑤ 成長試算'!D13+C9*'⑤ 成長試算'!D10+D9*'⑤ 成長試算'!D7)/E9 | J9: =IF('⑤ 成長試算'!M14="—","—",A9*'⑤ 成長試算'!M14+B9*'⑤ 成長試算'!M11+C9*'⑤ 成長試算'!M8+D9*'⑤ 成長試算'!M5) | K9: =IF('⑤ 成長試算'!M15="—","—",A9*'⑤ 成長試算'!M15+B9*'⑤ 成長試算'!M12+C9*'⑤ 成長試算'!M9+D9*'⑤ 成長試算'!M6) | L9: =IF('⑤ 成長試算'!M16="—","—",(A9*'⑤ 成長試算'!M16+B9*'⑤ 成長試算'!M13+C9*'⑤ 成長試算'!M10+D9*'⑤ 成長試算'!M7)/E9) | M9: COST上限ぴったり
A10: 0 | B10: 5 | C10: 0 | D10: 0 | E10: 5 | F10: 20 | G10: =A10*'⑤ 成長試算'!D14+B10*'⑤ 成長試算'!D11+C10*'⑤ 成長試算'!D8+D10*'⑤ 成長試算'!D5 | H10: =A10*'⑤ 成長試算'!D15+B10*'⑤ 成長試算'!D12+C10*'⑤ 成長試算'!D9+D10*'⑤ 成長試算'!D6 | I10: =(A10*'⑤ 成長試算'!D16+B10*'⑤ 成長試算'!D13+C10*'⑤ 成長試算'!D10+D10*'⑤ 成長試算'!D7)/E10 | J10: =IF('⑤ 成長試算'!M14="—","—",A10*'⑤ 成長試算'!M14+B10*'⑤ 成長試算'!M11+C10*'⑤ 成長試算'!M8+D10*'⑤ 成長試算'!M5) | K10: =IF('⑤ 成長試算'!M15="—","—",A10*'⑤ 成長試算'!M15+B10*'⑤ 成長試算'!M12+C10*'⑤ 成長試算'!M9+D10*'⑤ 成長試算'!M6) | L10: =IF('⑤ 成長試算'!M16="—","—",(A10*'⑤ 成長試算'!M16+B10*'⑤ 成長試算'!M13+C10*'⑤ 成長試算'!M10+D10*'⑤ 成長試算'!M7)/E10) | M10: COST上限ぴったり
A11: 3 | B11: 0 | C11: 0 | D11: 2 | E11: 5 | F11: 19 | G11: =A11*'⑤ 成長試算'!D14+B11*'⑤ 成長試算'!D11+C11*'⑤ 成長試算'!D8+D11*'⑤ 成長試算'!D5 | H11: =A11*'⑤ 成長試算'!D15+B11*'⑤ 成長試算'!D12+C11*'⑤ 成長試算'!D9+D11*'⑤ 成長試算'!D6 | I11: =(A11*'⑤ 成長試算'!D16+B11*'⑤ 成長試算'!D13+C11*'⑤ 成長試算'!D10+D11*'⑤ 成長試算'!D7)/E11 | J11: =IF('⑤ 成長試算'!M14="—","—",A11*'⑤ 成長試算'!M14+B11*'⑤ 成長試算'!M11+C11*'⑤ 成長試算'!M8+D11*'⑤ 成長試算'!M5) | K11: =IF('⑤ 成長試算'!M15="—","—",A11*'⑤ 成長試算'!M15+B11*'⑤ 成長試算'!M12+C11*'⑤ 成長試算'!M9+D11*'⑤ 成長試算'!M6) | L11: =IF('⑤ 成長試算'!M16="—","—",(A11*'⑤ 成長試算'!M16+B11*'⑤ 成長試算'!M13+C11*'⑤ 成長試算'!M10+D11*'⑤ 成長試算'!M7)/E11)
A12: 2 | B12: 1 | C12: 1 | D12: 1 | E12: 5 | F12: 19 | G12: =A12*'⑤ 成長試算'!D14+B12*'⑤ 成長試算'!D11+C12*'⑤ 成長試算'!D8+D12*'⑤ 成長試算'!D5 | H12: =A12*'⑤ 成長試算'!D15+B12*'⑤ 成長試算'!D12+C12*'⑤ 成長試算'!D9+D12*'⑤ 成長試算'!D6 | I12: =(A12*'⑤ 成長試算'!D16+B12*'⑤ 成長試算'!D13+C12*'⑤ 成長試算'!D10+D12*'⑤ 成長試算'!D7)/E12 | J12: =IF('⑤ 成長試算'!M14="—","—",A12*'⑤ 成長試算'!M14+B12*'⑤ 成長試算'!M11+C12*'⑤ 成長試算'!M8+D12*'⑤ 成長試算'!M5) | K12: =IF('⑤ 成長試算'!M15="—","—",A12*'⑤ 成長試算'!M15+B12*'⑤ 成長試算'!M12+C12*'⑤ 成長試算'!M9+D12*'⑤ 成長試算'!M6) | L12: =IF('⑤ 成長試算'!M16="—","—",(A12*'⑤ 成長試算'!M16+B12*'⑤ 成長試算'!M13+C12*'⑤ 成長試算'!M10+D12*'⑤ 成長試算'!M7)/E12)
A13: 2 | B13: 0 | C13: 3 | D13: 0 | E13: 5 | F13: 19 | G13: =A13*'⑤ 成長試算'!D14+B13*'⑤ 成長試算'!D11+C13*'⑤ 成長試算'!D8+D13*'⑤ 成長試算'!D5 | H13: =A13*'⑤ 成長試算'!D15+B13*'⑤ 成長試算'!D12+C13*'⑤ 成長試算'!D9+D13*'⑤ 成長試算'!D6 | I13: =(A13*'⑤ 成長試算'!D16+B13*'⑤ 成長試算'!D13+C13*'⑤ 成長試算'!D10+D13*'⑤ 成長試算'!D7)/E13 | J13: =IF('⑤ 成長試算'!M14="—","—",A13*'⑤ 成長試算'!M14+B13*'⑤ 成長試算'!M11+C13*'⑤ 成長試算'!M8+D13*'⑤ 成長試算'!M5) | K13: =IF('⑤ 成長試算'!M15="—","—",A13*'⑤ 成長試算'!M15+B13*'⑤ 成長試算'!M12+C13*'⑤ 成長試算'!M9+D13*'⑤ 成長試算'!M6) | L13: =IF('⑤ 成長試算'!M16="—","—",(A13*'⑤ 成長試算'!M16+B13*'⑤ 成長試算'!M13+C13*'⑤ 成長試算'!M10+D13*'⑤ 成長試算'!M7)/E13)
A14: 1 | B14: 3 | C14: 0 | D14: 1 | E14: 5 | F14: 19 | G14: =A14*'⑤ 成長試算'!D14+B14*'⑤ 成長試算'!D11+C14*'⑤ 成長試算'!D8+D14*'⑤ 成長試算'!D5 | H14: =A14*'⑤ 成長試算'!D15+B14*'⑤ 成長試算'!D12+C14*'⑤ 成長試算'!D9+D14*'⑤ 成長試算'!D6 | I14: =(A14*'⑤ 成長試算'!D16+B14*'⑤ 成長試算'!D13+C14*'⑤ 成長試算'!D10+D14*'⑤ 成長試算'!D7)/E14 | J14: =IF('⑤ 成長試算'!M14="—","—",A14*'⑤ 成長試算'!M14+B14*'⑤ 成長試算'!M11+C14*'⑤ 成長試算'!M8+D14*'⑤ 成長試算'!M5) | K14: =IF('⑤ 成長試算'!M15="—","—",A14*'⑤ 成長試算'!M15+B14*'⑤ 成長試算'!M12+C14*'⑤ 成長試算'!M9+D14*'⑤ 成長試算'!M6) | L14: =IF('⑤ 成長試算'!M16="—","—",(A14*'⑤ 成長試算'!M16+B14*'⑤ 成長試算'!M13+C14*'⑤ 成長試算'!M10+D14*'⑤ 成長試算'!M7)/E14)
A15: 1 | B15: 2 | C15: 2 | D15: 0 | E15: 5 | F15: 19 | G15: =A15*'⑤ 成長試算'!D14+B15*'⑤ 成長試算'!D11+C15*'⑤ 成長試算'!D8+D15*'⑤ 成長試算'!D5 | H15: =A15*'⑤ 成長試算'!D15+B15*'⑤ 成長試算'!D12+C15*'⑤ 成長試算'!D9+D15*'⑤ 成長試算'!D6 | I15: =(A15*'⑤ 成長試算'!D16+B15*'⑤ 成長試算'!D13+C15*'⑤ 成長試算'!D10+D15*'⑤ 成長試算'!D7)/E15 | J15: =IF('⑤ 成長試算'!M14="—","—",A15*'⑤ 成長試算'!M14+B15*'⑤ 成長試算'!M11+C15*'⑤ 成長試算'!M8+D15*'⑤ 成長試算'!M5) | K15: =IF('⑤ 成長試算'!M15="—","—",A15*'⑤ 成長試算'!M15+B15*'⑤ 成長試算'!M12+C15*'⑤ 成長試算'!M9+D15*'⑤ 成長試算'!M6) | L15: =IF('⑤ 成長試算'!M16="—","—",(A15*'⑤ 成長試算'!M16+B15*'⑤ 成長試算'!M13+C15*'⑤ 成長試算'!M10+D15*'⑤ 成長試算'!M7)/E15)
A16: 0 | B16: 4 | C16: 1 | D16: 0 | E16: 5 | F16: 19 | G16: =A16*'⑤ 成長試算'!D14+B16*'⑤ 成長試算'!D11+C16*'⑤ 成長試算'!D8+D16*'⑤ 成長試算'!D5 | H16: =A16*'⑤ 成長試算'!D15+B16*'⑤ 成長試算'!D12+C16*'⑤ 成長試算'!D9+D16*'⑤ 成長試算'!D6 | I16: =(A16*'⑤ 成長試算'!D16+B16*'⑤ 成長試算'!D13+C16*'⑤ 成長試算'!D10+D16*'⑤ 成長試算'!D7)/E16 | J16: =IF('⑤ 成長試算'!M14="—","—",A16*'⑤ 成長試算'!M14+B16*'⑤ 成長試算'!M11+C16*'⑤ 成長試算'!M8+D16*'⑤ 成長試算'!M5) | K16: =IF('⑤ 成長試算'!M15="—","—",A16*'⑤ 成長試算'!M15+B16*'⑤ 成長試算'!M12+C16*'⑤ 成長試算'!M9+D16*'⑤ 成長試算'!M6) | L16: =IF('⑤ 成長試算'!M16="—","—",(A16*'⑤ 成長試算'!M16+B16*'⑤ 成長試算'!M13+C16*'⑤ 成長試算'!M10+D16*'⑤ 成長試算'!M7)/E16)
A17: 2 | B17: 1 | C17: 0 | D17: 2 | E17: 5 | F17: 18 | G17: =A17*'⑤ 成長試算'!D14+B17*'⑤ 成長試算'!D11+C17*'⑤ 成長試算'!D8+D17*'⑤ 成長試算'!D5 | H17: =A17*'⑤ 成長試算'!D15+B17*'⑤ 成長試算'!D12+C17*'⑤ 成長試算'!D9+D17*'⑤ 成長試算'!D6 | I17: =(A17*'⑤ 成長試算'!D16+B17*'⑤ 成長試算'!D13+C17*'⑤ 成長試算'!D10+D17*'⑤ 成長試算'!D7)/E17 | J17: =IF('⑤ 成長試算'!M14="—","—",A17*'⑤ 成長試算'!M14+B17*'⑤ 成長試算'!M11+C17*'⑤ 成長試算'!M8+D17*'⑤ 成長試算'!M5) | K17: =IF('⑤ 成長試算'!M15="—","—",A17*'⑤ 成長試算'!M15+B17*'⑤ 成長試算'!M12+C17*'⑤ 成長試算'!M9+D17*'⑤ 成長試算'!M6) | L17: =IF('⑤ 成長試算'!M16="—","—",(A17*'⑤ 成長試算'!M16+B17*'⑤ 成長試算'!M13+C17*'⑤ 成長試算'!M10+D17*'⑤ 成長試算'!M7)/E17)
A18: 2 | B18: 0 | C18: 2 | D18: 1 | E18: 5 | F18: 18 | G18: =A18*'⑤ 成長試算'!D14+B18*'⑤ 成長試算'!D11+C18*'⑤ 成長試算'!D8+D18*'⑤ 成長試算'!D5 | H18: =A18*'⑤ 成長試算'!D15+B18*'⑤ 成長試算'!D12+C18*'⑤ 成長試算'!D9+D18*'⑤ 成長試算'!D6 | I18: =(A18*'⑤ 成長試算'!D16+B18*'⑤ 成長試算'!D13+C18*'⑤ 成長試算'!D10+D18*'⑤ 成長試算'!D7)/E18 | J18: =IF('⑤ 成長試算'!M14="—","—",A18*'⑤ 成長試算'!M14+B18*'⑤ 成長試算'!M11+C18*'⑤ 成長試算'!M8+D18*'⑤ 成長試算'!M5) | K18: =IF('⑤ 成長試算'!M15="—","—",A18*'⑤ 成長試算'!M15+B18*'⑤ 成長試算'!M12+C18*'⑤ 成長試算'!M9+D18*'⑤ 成長試算'!M6) | L18: =IF('⑤ 成長試算'!M16="—","—",(A18*'⑤ 成長試算'!M16+B18*'⑤ 成長試算'!M13+C18*'⑤ 成長試算'!M10+D18*'⑤ 成長試算'!M7)/E18)
A19: 1 | B19: 2 | C19: 1 | D19: 1 | E19: 5 | F19: 18 | G19: =A19*'⑤ 成長試算'!D14+B19*'⑤ 成長試算'!D11+C19*'⑤ 成長試算'!D8+D19*'⑤ 成長試算'!D5 | H19: =A19*'⑤ 成長試算'!D15+B19*'⑤ 成長試算'!D12+C19*'⑤ 成長試算'!D9+D19*'⑤ 成長試算'!D6 | I19: =(A19*'⑤ 成長試算'!D16+B19*'⑤ 成長試算'!D13+C19*'⑤ 成長試算'!D10+D19*'⑤ 成長試算'!D7)/E19 | J19: =IF('⑤ 成長試算'!M14="—","—",A19*'⑤ 成長試算'!M14+B19*'⑤ 成長試算'!M11+C19*'⑤ 成長試算'!M8+D19*'⑤ 成長試算'!M5) | K19: =IF('⑤ 成長試算'!M15="—","—",A19*'⑤ 成長試算'!M15+B19*'⑤ 成長試算'!M12+C19*'⑤ 成長試算'!M9+D19*'⑤ 成長試算'!M6) | L19: =IF('⑤ 成長試算'!M16="—","—",(A19*'⑤ 成長試算'!M16+B19*'⑤ 成長試算'!M13+C19*'⑤ 成長試算'!M10+D19*'⑤ 成長試算'!M7)/E19)
A20: 1 | B20: 1 | C20: 3 | D20: 0 | E20: 5 | F20: 18 | G20: =A20*'⑤ 成長試算'!D14+B20*'⑤ 成長試算'!D11+C20*'⑤ 成長試算'!D8+D20*'⑤ 成長試算'!D5 | H20: =A20*'⑤ 成長試算'!D15+B20*'⑤ 成長試算'!D12+C20*'⑤ 成長試算'!D9+D20*'⑤ 成長試算'!D6 | I20: =(A20*'⑤ 成長試算'!D16+B20*'⑤ 成長試算'!D13+C20*'⑤ 成長試算'!D10+D20*'⑤ 成長試算'!D7)/E20 | J20: =IF('⑤ 成長試算'!M14="—","—",A20*'⑤ 成長試算'!M14+B20*'⑤ 成長試算'!M11+C20*'⑤ 成長試算'!M8+D20*'⑤ 成長試算'!M5) | K20: =IF('⑤ 成長試算'!M15="—","—",A20*'⑤ 成長試算'!M15+B20*'⑤ 成長試算'!M12+C20*'⑤ 成長試算'!M9+D20*'⑤ 成長試算'!M6) | L20: =IF('⑤ 成長試算'!M16="—","—",(A20*'⑤ 成長試算'!M16+B20*'⑤ 成長試算'!M13+C20*'⑤ 成長試算'!M10+D20*'⑤ 成長試算'!M7)/E20)
A21: 0 | B21: 4 | C21: 0 | D21: 1 | E21: 5 | F21: 18 | G21: =A21*'⑤ 成長試算'!D14+B21*'⑤ 成長試算'!D11+C21*'⑤ 成長試算'!D8+D21*'⑤ 成長試算'!D5 | H21: =A21*'⑤ 成長試算'!D15+B21*'⑤ 成長試算'!D12+C21*'⑤ 成長試算'!D9+D21*'⑤ 成長試算'!D6 | I21: =(A21*'⑤ 成長試算'!D16+B21*'⑤ 成長試算'!D13+C21*'⑤ 成長試算'!D10+D21*'⑤ 成長試算'!D7)/E21 | J21: =IF('⑤ 成長試算'!M14="—","—",A21*'⑤ 成長試算'!M14+B21*'⑤ 成長試算'!M11+C21*'⑤ 成長試算'!M8+D21*'⑤ 成長試算'!M5) | K21: =IF('⑤ 成長試算'!M15="—","—",A21*'⑤ 成長試算'!M15+B21*'⑤ 成長試算'!M12+C21*'⑤ 成長試算'!M9+D21*'⑤ 成長試算'!M6) | L21: =IF('⑤ 成長試算'!M16="—","—",(A21*'⑤ 成長試算'!M16+B21*'⑤ 成長試算'!M13+C21*'⑤ 成長試算'!M10+D21*'⑤ 成長試算'!M7)/E21)
A22: 0 | B22: 3 | C22: 2 | D22: 0 | E22: 5 | F22: 18 | G22: =A22*'⑤ 成長試算'!D14+B22*'⑤ 成長試算'!D11+C22*'⑤ 成長試算'!D8+D22*'⑤ 成長試算'!D5 | H22: =A22*'⑤ 成長試算'!D15+B22*'⑤ 成長試算'!D12+C22*'⑤ 成長試算'!D9+D22*'⑤ 成長試算'!D6 | I22: =(A22*'⑤ 成長試算'!D16+B22*'⑤ 成長試算'!D13+C22*'⑤ 成長試算'!D10+D22*'⑤ 成長試算'!D7)/E22 | J22: =IF('⑤ 成長試算'!M14="—","—",A22*'⑤ 成長試算'!M14+B22*'⑤ 成長試算'!M11+C22*'⑤ 成長試算'!M8+D22*'⑤ 成長試算'!M5) | K22: =IF('⑤ 成長試算'!M15="—","—",A22*'⑤ 成長試算'!M15+B22*'⑤ 成長試算'!M12+C22*'⑤ 成長試算'!M9+D22*'⑤ 成長試算'!M6) | L22: =IF('⑤ 成長試算'!M16="—","—",(A22*'⑤ 成長試算'!M16+B22*'⑤ 成長試算'!M13+C22*'⑤ 成長試算'!M10+D22*'⑤ 成長試算'!M7)/E22)
A23: 2 | B23: 0 | C23: 1 | D23: 2 | E23: 5 | F23: 17 | G23: =A23*'⑤ 成長試算'!D14+B23*'⑤ 成長試算'!D11+C23*'⑤ 成長試算'!D8+D23*'⑤ 成長試算'!D5 | H23: =A23*'⑤ 成長試算'!D15+B23*'⑤ 成長試算'!D12+C23*'⑤ 成長試算'!D9+D23*'⑤ 成長試算'!D6 | I23: =(A23*'⑤ 成長試算'!D16+B23*'⑤ 成長試算'!D13+C23*'⑤ 成長試算'!D10+D23*'⑤ 成長試算'!D7)/E23 | J23: =IF('⑤ 成長試算'!M14="—","—",A23*'⑤ 成長試算'!M14+B23*'⑤ 成長試算'!M11+C23*'⑤ 成長試算'!M8+D23*'⑤ 成長試算'!M5) | K23: =IF('⑤ 成長試算'!M15="—","—",A23*'⑤ 成長試算'!M15+B23*'⑤ 成長試算'!M12+C23*'⑤ 成長試算'!M9+D23*'⑤ 成長試算'!M6) | L23: =IF('⑤ 成長試算'!M16="—","—",(A23*'⑤ 成長試算'!M16+B23*'⑤ 成長試算'!M13+C23*'⑤ 成長試算'!M10+D23*'⑤ 成長試算'!M7)/E23)
A24: 1 | B24: 2 | C24: 0 | D24: 2 | E24: 5 | F24: 17 | G24: =A24*'⑤ 成長試算'!D14+B24*'⑤ 成長試算'!D11+C24*'⑤ 成長試算'!D8+D24*'⑤ 成長試算'!D5 | H24: =A24*'⑤ 成長試算'!D15+B24*'⑤ 成長試算'!D12+C24*'⑤ 成長試算'!D9+D24*'⑤ 成長試算'!D6 | I24: =(A24*'⑤ 成長試算'!D16+B24*'⑤ 成長試算'!D13+C24*'⑤ 成長試算'!D10+D24*'⑤ 成長試算'!D7)/E24 | J24: =IF('⑤ 成長試算'!M14="—","—",A24*'⑤ 成長試算'!M14+B24*'⑤ 成長試算'!M11+C24*'⑤ 成長試算'!M8+D24*'⑤ 成長試算'!M5) | K24: =IF('⑤ 成長試算'!M15="—","—",A24*'⑤ 成長試算'!M15+B24*'⑤ 成長試算'!M12+C24*'⑤ 成長試算'!M9+D24*'⑤ 成長試算'!M6) | L24: =IF('⑤ 成長試算'!M16="—","—",(A24*'⑤ 成長試算'!M16+B24*'⑤ 成長試算'!M13+C24*'⑤ 成長試算'!M10+D24*'⑤ 成長試算'!M7)/E24)
A25: 1 | B25: 1 | C25: 2 | D25: 1 | E25: 5 | F25: 17 | G25: =A25*'⑤ 成長試算'!D14+B25*'⑤ 成長試算'!D11+C25*'⑤ 成長試算'!D8+D25*'⑤ 成長試算'!D5 | H25: =A25*'⑤ 成長試算'!D15+B25*'⑤ 成長試算'!D12+C25*'⑤ 成長試算'!D9+D25*'⑤ 成長試算'!D6 | I25: =(A25*'⑤ 成長試算'!D16+B25*'⑤ 成長試算'!D13+C25*'⑤ 成長試算'!D10+D25*'⑤ 成長試算'!D7)/E25 | J25: =IF('⑤ 成長試算'!M14="—","—",A25*'⑤ 成長試算'!M14+B25*'⑤ 成長試算'!M11+C25*'⑤ 成長試算'!M8+D25*'⑤ 成長試算'!M5) | K25: =IF('⑤ 成長試算'!M15="—","—",A25*'⑤ 成長試算'!M15+B25*'⑤ 成長試算'!M12+C25*'⑤ 成長試算'!M9+D25*'⑤ 成長試算'!M6) | L25: =IF('⑤ 成長試算'!M16="—","—",(A25*'⑤ 成長試算'!M16+B25*'⑤ 成長試算'!M13+C25*'⑤ 成長試算'!M10+D25*'⑤ 成長試算'!M7)/E25)
A26: 1 | B26: 0 | C26: 4 | D26: 0 | E26: 5 | F26: 17 | G26: =A26*'⑤ 成長試算'!D14+B26*'⑤ 成長試算'!D11+C26*'⑤ 成長試算'!D8+D26*'⑤ 成長試算'!D5 | H26: =A26*'⑤ 成長試算'!D15+B26*'⑤ 成長試算'!D12+C26*'⑤ 成長試算'!D9+D26*'⑤ 成長試算'!D6 | I26: =(A26*'⑤ 成長試算'!D16+B26*'⑤ 成長試算'!D13+C26*'⑤ 成長試算'!D10+D26*'⑤ 成長試算'!D7)/E26 | J26: =IF('⑤ 成長試算'!M14="—","—",A26*'⑤ 成長試算'!M14+B26*'⑤ 成長試算'!M11+C26*'⑤ 成長試算'!M8+D26*'⑤ 成長試算'!M5) | K26: =IF('⑤ 成長試算'!M15="—","—",A26*'⑤ 成長試算'!M15+B26*'⑤ 成長試算'!M12+C26*'⑤ 成長試算'!M9+D26*'⑤ 成長試算'!M6) | L26: =IF('⑤ 成長試算'!M16="—","—",(A26*'⑤ 成長試算'!M16+B26*'⑤ 成長試算'!M13+C26*'⑤ 成長試算'!M10+D26*'⑤ 成長試算'!M7)/E26)
A27: 0 | B27: 3 | C27: 1 | D27: 1 | E27: 5 | F27: 17 | G27: =A27*'⑤ 成長試算'!D14+B27*'⑤ 成長試算'!D11+C27*'⑤ 成長試算'!D8+D27*'⑤ 成長試算'!D5 | H27: =A27*'⑤ 成長試算'!D15+B27*'⑤ 成長試算'!D12+C27*'⑤ 成長試算'!D9+D27*'⑤ 成長試算'!D6 | I27: =(A27*'⑤ 成長試算'!D16+B27*'⑤ 成長試算'!D13+C27*'⑤ 成長試算'!D10+D27*'⑤ 成長試算'!D7)/E27 | J27: =IF('⑤ 成長試算'!M14="—","—",A27*'⑤ 成長試算'!M14+B27*'⑤ 成長試算'!M11+C27*'⑤ 成長試算'!M8+D27*'⑤ 成長試算'!M5) | K27: =IF('⑤ 成長試算'!M15="—","—",A27*'⑤ 成長試算'!M15+B27*'⑤ 成長試算'!M12+C27*'⑤ 成長試算'!M9+D27*'⑤ 成長試算'!M6) | L27: =IF('⑤ 成長試算'!M16="—","—",(A27*'⑤ 成長試算'!M16+B27*'⑤ 成長試算'!M13+C27*'⑤ 成長試算'!M10+D27*'⑤ 成長試算'!M7)/E27)
A28: 0 | B28: 2 | C28: 3 | D28: 0 | E28: 5 | F28: 17 | G28: =A28*'⑤ 成長試算'!D14+B28*'⑤ 成長試算'!D11+C28*'⑤ 成長試算'!D8+D28*'⑤ 成長試算'!D5 | H28: =A28*'⑤ 成長試算'!D15+B28*'⑤ 成長試算'!D12+C28*'⑤ 成長試算'!D9+D28*'⑤ 成長試算'!D6 | I28: =(A28*'⑤ 成長試算'!D16+B28*'⑤ 成長試算'!D13+C28*'⑤ 成長試算'!D10+D28*'⑤ 成長試算'!D7)/E28 | J28: =IF('⑤ 成長試算'!M14="—","—",A28*'⑤ 成長試算'!M14+B28*'⑤ 成長試算'!M11+C28*'⑤ 成長試算'!M8+D28*'⑤ 成長試算'!M5) | K28: =IF('⑤ 成長試算'!M15="—","—",A28*'⑤ 成長試算'!M15+B28*'⑤ 成長試算'!M12+C28*'⑤ 成長試算'!M9+D28*'⑤ 成長試算'!M6) | L28: =IF('⑤ 成長試算'!M16="—","—",(A28*'⑤ 成長試算'!M16+B28*'⑤ 成長試算'!M13+C28*'⑤ 成長試算'!M10+D28*'⑤ 成長試算'!M7)/E28)
A29: 2 | B29: 0 | C29: 0 | D29: 3 | E29: 5 | F29: 16 | G29: =A29*'⑤ 成長試算'!D14+B29*'⑤ 成長試算'!D11+C29*'⑤ 成長試算'!D8+D29*'⑤ 成長試算'!D5 | H29: =A29*'⑤ 成長試算'!D15+B29*'⑤ 成長試算'!D12+C29*'⑤ 成長試算'!D9+D29*'⑤ 成長試算'!D6 | I29: =(A29*'⑤ 成長試算'!D16+B29*'⑤ 成長試算'!D13+C29*'⑤ 成長試算'!D10+D29*'⑤ 成長試算'!D7)/E29 | J29: =IF('⑤ 成長試算'!M14="—","—",A29*'⑤ 成長試算'!M14+B29*'⑤ 成長試算'!M11+C29*'⑤ 成長試算'!M8+D29*'⑤ 成長試算'!M5) | K29: =IF('⑤ 成長試算'!M15="—","—",A29*'⑤ 成長試算'!M15+B29*'⑤ 成長試算'!M12+C29*'⑤ 成長試算'!M9+D29*'⑤ 成長試算'!M6) | L29: =IF('⑤ 成長試算'!M16="—","—",(A29*'⑤ 成長試算'!M16+B29*'⑤ 成長試算'!M13+C29*'⑤ 成長試算'!M10+D29*'⑤ 成長試算'!M7)/E29)
A30: 1 | B30: 1 | C30: 1 | D30: 2 | E30: 5 | F30: 16 | G30: =A30*'⑤ 成長試算'!D14+B30*'⑤ 成長試算'!D11+C30*'⑤ 成長試算'!D8+D30*'⑤ 成長試算'!D5 | H30: =A30*'⑤ 成長試算'!D15+B30*'⑤ 成長試算'!D12+C30*'⑤ 成長試算'!D9+D30*'⑤ 成長試算'!D6 | I30: =(A30*'⑤ 成長試算'!D16+B30*'⑤ 成長試算'!D13+C30*'⑤ 成長試算'!D10+D30*'⑤ 成長試算'!D7)/E30 | J30: =IF('⑤ 成長試算'!M14="—","—",A30*'⑤ 成長試算'!M14+B30*'⑤ 成長試算'!M11+C30*'⑤ 成長試算'!M8+D30*'⑤ 成長試算'!M5) | K30: =IF('⑤ 成長試算'!M15="—","—",A30*'⑤ 成長試算'!M15+B30*'⑤ 成長試算'!M12+C30*'⑤ 成長試算'!M9+D30*'⑤ 成長試算'!M6) | L30: =IF('⑤ 成長試算'!M16="—","—",(A30*'⑤ 成長試算'!M16+B30*'⑤ 成長試算'!M13+C30*'⑤ 成長試算'!M10+D30*'⑤ 成長試算'!M7)/E30)
A31: 1 | B31: 0 | C31: 3 | D31: 1 | E31: 5 | F31: 16 | G31: =A31*'⑤ 成長試算'!D14+B31*'⑤ 成長試算'!D11+C31*'⑤ 成長試算'!D8+D31*'⑤ 成長試算'!D5 | H31: =A31*'⑤ 成長試算'!D15+B31*'⑤ 成長試算'!D12+C31*'⑤ 成長試算'!D9+D31*'⑤ 成長試算'!D6 | I31: =(A31*'⑤ 成長試算'!D16+B31*'⑤ 成長試算'!D13+C31*'⑤ 成長試算'!D10+D31*'⑤ 成長試算'!D7)/E31 | J31: =IF('⑤ 成長試算'!M14="—","—",A31*'⑤ 成長試算'!M14+B31*'⑤ 成長試算'!M11+C31*'⑤ 成長試算'!M8+D31*'⑤ 成長試算'!M5) | K31: =IF('⑤ 成長試算'!M15="—","—",A31*'⑤ 成長試算'!M15+B31*'⑤ 成長試算'!M12+C31*'⑤ 成長試算'!M9+D31*'⑤ 成長試算'!M6) | L31: =IF('⑤ 成長試算'!M16="—","—",(A31*'⑤ 成長試算'!M16+B31*'⑤ 成長試算'!M13+C31*'⑤ 成長試算'!M10+D31*'⑤ 成長試算'!M7)/E31)
A32: 0 | B32: 3 | C32: 0 | D32: 2 | E32: 5 | F32: 16 | G32: =A32*'⑤ 成長試算'!D14+B32*'⑤ 成長試算'!D11+C32*'⑤ 成長試算'!D8+D32*'⑤ 成長試算'!D5 | H32: =A32*'⑤ 成長試算'!D15+B32*'⑤ 成長試算'!D12+C32*'⑤ 成長試算'!D9+D32*'⑤ 成長試算'!D6 | I32: =(A32*'⑤ 成長試算'!D16+B32*'⑤ 成長試算'!D13+C32*'⑤ 成長試算'!D10+D32*'⑤ 成長試算'!D7)/E32 | J32: =IF('⑤ 成長試算'!M14="—","—",A32*'⑤ 成長試算'!M14+B32*'⑤ 成長試算'!M11+C32*'⑤ 成長試算'!M8+D32*'⑤ 成長試算'!M5) | K32: =IF('⑤ 成長試算'!M15="—","—",A32*'⑤ 成長試算'!M15+B32*'⑤ 成長試算'!M12+C32*'⑤ 成長試算'!M9+D32*'⑤ 成長試算'!M6) | L32: =IF('⑤ 成長試算'!M16="—","—",(A32*'⑤ 成長試算'!M16+B32*'⑤ 成長試算'!M13+C32*'⑤ 成長試算'!M10+D32*'⑤ 成長試算'!M7)/E32)
A33: 0 | B33: 2 | C33: 2 | D33: 1 | E33: 5 | F33: 16 | G33: =A33*'⑤ 成長試算'!D14+B33*'⑤ 成長試算'!D11+C33*'⑤ 成長試算'!D8+D33*'⑤ 成長試算'!D5 | H33: =A33*'⑤ 成長試算'!D15+B33*'⑤ 成長試算'!D12+C33*'⑤ 成長試算'!D9+D33*'⑤ 成長試算'!D6 | I33: =(A33*'⑤ 成長試算'!D16+B33*'⑤ 成長試算'!D13+C33*'⑤ 成長試算'!D10+D33*'⑤ 成長試算'!D7)/E33 | J33: =IF('⑤ 成長試算'!M14="—","—",A33*'⑤ 成長試算'!M14+B33*'⑤ 成長試算'!M11+C33*'⑤ 成長試算'!M8+D33*'⑤ 成長試算'!M5) | K33: =IF('⑤ 成長試算'!M15="—","—",A33*'⑤ 成長試算'!M15+B33*'⑤ 成長試算'!M12+C33*'⑤ 成長試算'!M9+D33*'⑤ 成長試算'!M6) | L33: =IF('⑤ 成長試算'!M16="—","—",(A33*'⑤ 成長試算'!M16+B33*'⑤ 成長試算'!M13+C33*'⑤ 成長試算'!M10+D33*'⑤ 成長試算'!M7)/E33)
